Workbook

Sheet Instrucciones
A1: Libro registro de facturas con comprobaciones · CIRAMEVA Despachos (gratis; cirameva.com/despachos/contabilidad-por-lotes/)
A3: 1. Rellena solo las celdas amarillas de «Emitidas» y «Recibidas»: fecha, número, nombre, NIF, bases por tipo de IVA, retención y el total que pone la factura.
A4: 2. La hoja calcula las cuotas, el total y te avisa en verde/rojo: ¿Cuadra? (total de la factura frente al calculado, margen 2 céntimos), ¿NIF válido? (letra del DNI/NIE y dígito de control del CIF) y ¿Duplicada? (mismo número y NIF).
A5: 3. «Resumen 303» suma por trimestre el IVA devengado y el soportado. Es orientativo: no incluye prorrata, inversión del sujeto pasivo, bienes de inversión, recargo de equivalencia ni operaciones intracomunitarias. Revísalo con tu asesoría antes de presentar.
A6: 4. «Conciliación» compara el saldo del banco con el de tu contabilidad y lista las partidas pendientes.
A8: Las filas de ejemplo (datos inventados) se pueden borrar. ¿Muchas facturas? Te las registramos y conciliamos por lotes en 48 h: 0,30 € por factura; el primer lote de 50, gratis.

Sheet Emitidas
A1: Fecha | B1: N.º factura | C1: Cliente | D1: NIF | E1: Base 21 % | F1: Base 10 % | G1: Base 4 % | H1: Base exenta o 0 % | I1: Cuota 21 % | J1: Cuota 10 % | K1: Cuota 4 % | L1: Retención IRPF | M1: Total en la factura | N1: Total calculado | O1: ¿Cuadra? | P1: ¿NIF válido? | Q1: ¿Duplicada? | R1: Trimestre | S1: Cuenta PGC
A2: 46206 | B2: 2026-041 | C2: Cliente Ejemplo, S.L. | D2: B12345674 | E2: 1200 | I2: =IF(E2="","",ROUND(E2*0.21,2)) | J2: =IF(F2="","",ROUND(F2*0.1,2)) | K2: =IF(G2="","",ROUND(G2*0.04,2)) | L2: 180 | M2: 1272 | N2: =IF(A2="","",SUM(E2:K2)-N(L2)) | O2: =IF(OR(A2="",M2=""),"",IF(ABS(M2-N2)<=0.02,"OK","REVISAR")) | P2: =IF(D2="","",IF(LEN(TRIM(D2))<>9,"REVISAR",IFERROR(IF(OR(ISNUMBER(VALUE(LEFT(UPPER(TRIM(D2)),1))),LEFT(UPPER(TRIM(D2)),1)="X",LEFT(UPPER(TRIM(D2)),1)="Y",LEFT(UPPER(TRIM(D2)),1)="Z"),IF(MID("TRWAGMYFPDXBNJZSQVHLCKE",MOD(VALUE(SUBSTITUTE(SUBSTITUTE(SUBSTITUTE(LEFT(UPPER(TRIM(D2)),8),"X","0"),"Y","1"),"Z","2")),23)+1,1)=RIGHT(UPPER(TRIM(D2)),1),"OK","REVISAR"),IF(OR(RIGHT(UPPER(TRIM(D2)),1)=TEXT(MOD(10-MOD((VALUE(MID(UPPER(TRIM(D2)),3,1))+VALUE(MID(UPPER(TRIM(D2)),5,1))+VALUE(MID(UPPER(TRIM(D2)),7,1)))+(INT(2*VALUE(MID(UPPER(TRIM(D2)),2,1))/10)+MOD(2*VALUE(MID(UPPER(TRIM(D2)),2,1)),10))+(INT(2*VALUE(MID(UPPER(TRIM(D2)),4,1))/10)+MOD(2*VALUE(MID(UPPER(TRIM(D2)),4,1)),10))+(INT(2*VALUE(MID(UPPER(TRIM(D2)),6,1))/10)+MOD(2*VALUE(MID(UPPER(TRIM(D2)),6,1)),10))+(INT(2*VALUE(MID(UPPER(TRIM(D2)),8,1))/10)+MOD(2*VALUE(MID(UPPER(TRIM(D2)),8,1)),10)),10),10),"0"),RIGHT(UPPER(TRIM(D2)),1)=MID("JABCDEFGHI",MOD(10-MOD((VALUE(MID(UPPER(TRIM(D2)),3,1))+VALUE(MID(UPPER(TRIM(D2)),5,1))+VALUE(MID(UPPER(TRIM(D2)),7,1)))+(INT(2*VALUE(MID(UPPER(TRIM(D2)),2,1))/10)+MOD(2*VALUE(MID(UPPER(TRIM(D2)),2,1)),10))+(INT(2*VALUE(MID(UPPER(TRIM(D2)),4,1))/10)+MOD(2*VALUE(MID(UPPER(TRIM(D2)),4,1)),10))+(INT(2*VALUE(MID(UPPER(TRIM(D2)),6,1))/10)+MOD(2*VALUE(MID(UPPER(TRIM(D2)),6,1)),10))+(INT(2*VALUE(MID(UPPER(TRIM(D2)),8,1))/10)+MOD(2*VALUE(MID(UPPER(TRIM(D2)),8,1)),10)),10),10)+1,1)),"OK","REVISAR")),"REVISAR"))) | Q2: =IF(B2="","",IF(COUNTIFS($B$2:$B$501,B2,$D$2:$D$501,D2)>1,"DUPLICADA","")) | R2: =IF(A2="","",ROUNDUP(MONTH(A2)/3,0)) | S2: 705
A3: 46254 | B3: 2026-042 | C3: Cliente Ejemplo, S.L. | D3: B12345674 | E3: 800 | I3: =IF(E3="","",ROUND(E3*0.21,2)) | J3: =IF(F3="","",ROUND(F3*0.1,2)) | K3: =IF(G3="","",ROUND(G3*0.04,2)) | M3: 968 | N3: =IF(A3="","",SUM(E3:K3)-N(L3)) | O3: =IF(OR(A3="",M3=""),"",IF(ABS(M3-N3)<=0.02,"OK","REVISAR")) | P3: =IF(D3="","",IF(LEN(TRIM(D3))<>9,"REVISAR",IFERROR(IF(OR(ISNUMBER(VALUE(LEFT(UPPER(TRIM(D3)),1))),LEFT(UPPER(TRIM(D3)),1)="X",LEFT(UPPER(TRIM(D3)),1)="Y",LEFT(UPPER(TRIM(D3)),1)="Z"),IF(MID("TRWAGMYFPDXBNJZSQVHLCKE",MOD(VALUE(SUBSTITUTE(SUBSTITUTE(SUBSTITUTE(LEFT(UPPER(TRIM(D3)),8),"X","0"),"Y","1"),"Z","2")),23)+1,1)=RIGHT(UPPER(TRIM(D3)),1),"OK","REVISAR"),IF(OR(RIGHT(UPPER(TRIM(D3)),1)=TEXT(MOD(10-MOD((VALUE(MID(UPPER(TRIM(D3)),3,1))+VALUE(MID(UPPER(TRIM(D3)),5,1))+VALUE(MID(UPPER(TRIM(D3)),7,1)))+(INT(2*VALUE(MID(UPPER(TRIM(D3)),2,1))/10)+MOD(2*VALUE(MID(UPPER(TRIM(D3)),2,1)),10))+(INT(2*VALUE(MID(UPPER(TRIM(D3)),4,1))/10)+MOD(2*VALUE(MID(UPPER(TRIM(D3)),4,1)),10))+(INT(2*VALUE(MID(UPPER(TRIM(D3)),6,1))/10)+MOD(2*VALUE(MID(UPPER(TRIM(D3)),6,1)),10))+(INT(2*VALUE(MID(UPPER(TRIM(D3)),8,1))/10)+MOD(2*VALUE(MID(UPPER(TRIM(D3)),8,1)),10)),10),10),"0"),RIGHT(UPPER(TRIM(D3)),1)=MID("JABCDEFGHI",MOD(10-MOD((VALUE(MID(UPPER(TRIM(D3)),3,1))+VALUE(MID(UPPER(TRIM(D3)),5,1))+VALUE(MID(UPPER(TRIM(D3)),7,1)))+(INT(2*VALUE(MID(UPPER(TRIM(D3)),2,1))/10)+MOD(2*VALUE(MID(UPPER(TRIM(D3)),2,1)),10))+(INT(2*VALUE(MID(UPPER(TRIM(D3)),4,1))/10)+MOD(2*VALUE(MID(UPPER(TRIM(D3)),4,1)),10))+(INT(2*VALUE(MID(UPPER(TRIM(D3)),6,1))/10)+MOD(2*VALUE(MID(UPPER(TRIM(D3)),6,1)),10))+(INT(2*VALUE(MID(UPPER(TRIM(D3)),8,1))/10)+MOD(2*VALUE(MID(UPPER(TRIM(D3)),8,1)),10)),10),10)+1,1)),"OK","REVISAR")),"REVISAR"))) | Q3: =IF(B3="","",IF(COUNTIFS($B$2:$B$501,B3,$D$2:$D$501,D3)>1,"DUPLICADA","")) | R3: =IF(A3="","",ROUNDUP(MONTH(A3)/3,0)) | S3: 705
A4: 46295 | B4: 2026-043 | C4: Juan Ejemplo Pérez | D4: 12345678Z | E4: 300 | I4: =IF(E4="","",ROUND(E4*0.21,2)) | J4: =IF(F4="","",ROUND(F4*0.1,2)) | K4: =IF(G4="","",ROUND(G4*0.04,2)) | M4: 363 | N4: =IF(A4="","",SUM(E4:K4)-N(L4)) | O4: =IF(OR(A4="",M4=""),"",IF(ABS(M4-N4)<=0.02,"OK","REVISAR")) | P4: =IF(D4="","",IF(LEN(TRIM(D4))<>9,"REVISAR",IFERROR(IF(OR(ISNUMBER(VALUE(LEFT(UPPER(TRIM(D4)),1))),LEFT(UPPER(TRIM(D4)),1)="X",LEFT(UPPER(TRIM(D4)),1)="Y",LEFT(UPPER(TRIM(D4)),1)="Z"),IF(MID("TRWAGMYFPDXBNJZSQVHLCKE",MOD(VALUE(SUBSTITUTE(SUBSTITUTE(SUBSTITUTE(LEFT(UPPER(TRIM(D4)),8),"X","0"),"Y","1"),"Z","2")),23)+1,1)=RIGHT(UPPER(TRIM(D4)),1),"OK","REVISAR"),IF(OR(RIGHT(UPPER(TRIM(D4)),1)=TEXT(MOD(10-MOD((VALUE(MID(UPPER(TRIM(D4)),3,1))+VALUE(MID(UPPER(TRIM(D4)),5,1))+VALUE(MID(UPPER(TRIM(D4)),7,1)))+(INT(2*VALUE(MID(UPPER(TRIM(D4)),2,1))/10)+MOD(2*VALUE(MID(UPPER(TRIM(D4)),2,1)),10))+(INT(2*VALUE(MID(UPPER(TRIM(D4)),4,1))/10)+MOD(2*VALUE(MID(UPPER(TRIM(D4)),4,1)),10))+(INT(2*VALUE(MID(UPPER(TRIM(D4)),6,1))/10)+MOD(2*VALUE(MID(UPPER(TRIM(D4)),6,1)),10))+(INT(2*VALUE(MID(UPPER(TRIM(D4)),8,1))/10)+MOD(2*VALUE(MID(UPPER(TRIM(D4)),8,1)),10)),10),10),"0"),RIGHT(UPPER(TRIM(D4)),1)=MID("JABCDEFGHI",MOD(10-MOD((VALUE(MID(UPPER(TRIM(D4)),3,1))+VALUE(MID(UPPER(TRIM(D4)),5,1))+VALUE(MID(UPPER(TRIM(D4)),7,1)))+(INT(2*VALUE(MID(UPPER(TRIM(D4)),2,1))/10)+MOD(2*VALUE(MID(UPPER(TRIM(D4)),2,1)),10))+(INT(2*VALUE(MID(UPPER(TRIM(D4)),4,1))/10)+MOD(2*VALUE(MID(UPPER(TRIM(D4)),4,1)),10))+(INT(2*VALUE(MID(UPPER(TRIM(D4)),6,1))/10)+MOD(2*VALUE(MID(UPPER(TRIM(D4)),6,1)),10))+(INT(2*VALUE(MID(UPPER(TRIM(D4)),8,1))/10)+MOD(2*VALUE(MID(UPPER(TRIM(D4)),8,1)),10)),10),10)+1,1)),"OK","REVISAR")),"REVISAR"))) | Q4: =IF(B4="","",IF(COUNTIFS($B$2:$B$501,B4,$D$2:$D$501,D4)>1,"DUPLICADA","")) | R4: =IF(A4="","",ROUNDUP(MONTH(A4)/3,0)) | S4: 705
I5: =IF(E5="","",ROUND(E5*0.21,2)) | J5: =IF(F5="","",ROUND(F5*0.1,2)) | K5: =IF(G5="","",ROUND(G5*0.04,2)) | N5: =IF(A5="","",SUM(E5:K5)-N(L5)) | O5: =IF(OR(A5="",M5=""),"",IF(ABS(M5-N5)<=0.02,"OK","REVISAR")) | P5: =IF(D5="","",IF(LEN(TRIM(D5))<>9,"REVISAR",IFERROR(IF(OR(ISNUMBER(VALUE(LEFT(UPPER(TRIM(D5)),1))),LEFT(UPPER(TRIM(D5)),1)="X",LEFT(UPPER(TRIM(D5)),1)="Y",LEFT(UPPER(TRIM(D5)),1)="Z"),IF(MID("TRWAGMYFPDXBNJZSQVHLCKE",MOD(VALUE(SUBSTITUTE(SUBSTITUTE(SUBSTITUTE(LEFT(UPPER(TRIM(D5)),8),"X","0"),"Y","1"),"Z","2")),23)+1,1)=RIGHT(UPPER(TRIM(D5)),1),"OK","REVISAR"),IF(OR(RIGHT(UPPER(TRIM(D5)),1)=TEXT(MOD(10-MOD((VALUE(MID(UPPER(TRIM(D5)),3,1))+VALUE(MID(UPPER(TRIM(D5)),5,1))+VALUE(MID(UPPER(TRIM(D5)),7,1)))+(INT(2*VALUE(MID(UPPER(TRIM(D5)),2,1))/10)+MOD(2*VALUE(MID(UPPER(TRIM(D5)),2,1)),10))+(INT(2*VALUE(MID(UPPER(TRIM(D5)),4,1))/10)+MOD(2*VALUE(MID(UPPER(TRIM(D5)),4,1)),10))+(INT(2*VALUE(MID(UPPER(TRIM(D5)),6,1))/10)+MOD(2*VALUE(MID(UPPER(TRIM(D5)),6,1)),10))+(INT(2*VALUE(MID(UPPER(TRIM(D5)),8,1))/10)+MOD(2*VALUE(MID(UPPER(TRIM(D5)),8,1)),10)),10),10),"0"),RIGHT(UPPER(TRIM(D5)),1)=MID("JABCDEFGHI",MOD(10-MOD((VALUE(MID(UPPER(TRIM(D5)),3,1))+VALUE(MID(UPPER(TRIM(D5)),5,1))+VALUE(MID(UPPER(TRIM(D5)),7,1)))+(INT(2*VALUE(MID(UPPER(TRIM(D5)),2,1))/10)+MOD(2*VALUE(MID(UPPER(TRIM(D5)),2,1)),10))+(INT(2*VALUE(MID(UPPER(TRIM(D5)),4,1))/10)+MOD(2*VALUE(MID(UPPER(TRIM(D5)),4,1)),10))+(INT(2*VALUE(MID(UPPER(TRIM(D5)),6,1))/10)+MOD(2*VALUE(MID(UPPER(TRIM(D5)),6,1)),10))+(INT(2*VALUE(MID(UPPER(TRIM(D5)),8,1))/10)+MOD(2*VALUE(MID(UPPER(TRIM(D5)),8,1)),10)),10),10)+1,1)),"OK","REVISAR")),"REVISAR"))) | Q5: =IF(B5="","",IF(COUNTIFS($B$2:$B$501,B5,$D$2:$D$501,D5)>1,"DUPLICADA","")) | R5: =IF(A5="","",ROUNDUP(MONTH(A5)/3,0))
I6: =IF(E6="","",ROUND(E6*0.21,2)) | J6: =IF(F6="","",ROUND(F6*0.1,2)) | K6: =IF(G6="","",ROUND(G6*0.04,2)) | N6: =IF(A6="","",SUM(E6:K6)-N(L6)) | O6: =IF(OR(A6="",M6=""),"",IF(ABS(M6-N6)<=0.02,"OK","REVISAR")) | P6: =IF(D6="","",IF(LEN(TRIM(D6))<>9,"REVISAR",IFERROR(IF(OR(ISNUMBER(VALUE(LEFT(UPPER(TRIM(D6)),1))),LEFT(UPPER(TRIM(D6)),1)="X",LEFT(UPPER(TRIM(D6)),1)="Y",LEFT(UPPER(TRIM(D6)),1)="Z"),IF(MID("TRWAGMYFPDXBNJZSQVHLCKE",MOD(VALUE(SUBSTITUTE(SUBSTITUTE(SUBSTITUTE(LEFT(UPPER(TRIM(D6)),8),"X","0"),"Y","1"),"Z","2")),23)+1,1)=RIGHT(UPPER(TRIM(D6)),1),"OK","REVISAR"),IF(OR(RIGHT(UPPER(TRIM(D6)),1)=TEXT(MOD(10-MOD((VALUE(MID(UPPER(TRIM(D6)),3,1))+VALUE(MID(UPPER(TRIM(D6)),5,1))+VALUE(MID(UPPER(TRIM(D6)),7,1)))+(INT(2*VALUE(MID(UPPER(TRIM(D6)),2,1))/10)+MOD(2*VALUE(MID(UPPER(TRIM(D6)),2,1)),10))+(INT(2*VALUE(MID(UPPER(TRIM(D6)),4,1))/10)+MOD(2*VALUE(MID(UPPER(TRIM(D6)),4,1)),10))+(INT(2*VALUE(MID(UPPER(TRIM(D6)),6,1))/10)+MOD(2*VALUE(MID(UPPER(TRIM(D6)),6,1)),10))+(INT(2*VALUE(MID(UPPER(TRIM(D6)),8,1))/10)+MOD(2*VALUE(MID(UPPER(TRIM(D6)),8,1)),10)),10),10),"0"),RIGHT(UPPER(TRIM(D6)),1)=MID("JABCDEFGHI",MOD(10-MOD((VALUE(MID(UPPER(TRIM(D6)),3,1))+VALUE(MID(UPPER(TRIM(D6)),5,1))+VALUE(MID(UPPER(TRIM(D6)),7,1)))+(INT(2*VALUE(MID(UPPER(TRIM(D6)),2,1))/10)+MOD(2*VALUE(MID(UPPER(TRIM(D6)),2,1)),10))+(INT(2*VALUE(MID(UPPER(TRIM(D6)),4,1))/10)+MOD(2*VALUE(MID(UPPER(TRIM(D6)),4,1)),10))+(INT(2*VALUE(MID(UPPER(TRIM(D6)),6,1))/10)+MOD(2*VALUE(MID(UPPER(TRIM(D6)),6,1)),10))+(INT(2*VALUE(MID(UPPER(TRIM(D6)),8,1))/10)+MOD(2*VALUE(MID(UPPER(TRIM(D6)),8,1)),10)),10),10)+1,1)),"OK","REVISAR")),"REVISAR"))) | Q6: =IF(B6="","",IF(COUNTIFS($B$2:$B$501,B6,$D$2:$D$501,D6)>1,"DUPLICADA","")) | R6: =IF(A6="","",ROUNDUP(MONTH(A6)/3,0))
I7: =IF(E7="","",ROUND(E7*0.21,2)) | J7: =IF(F7="","",ROUND(F7*0.1,2)) | K7: =IF(G7="","",ROUND(G7*0.04,2)) | N7: =IF(A7="","",SUM(E7:K7)-N(L7)) | O7: =IF(OR(A7="",M7=""),"",IF(ABS(M7-N7)<=0.02,"OK","REVISAR")) | P7: =IF(D7="","",IF(LEN(TRIM(D7))<>9,"REVISAR",IFERROR(IF(OR(ISNUMBER(VALUE(LEFT(UPPER(TRIM(D7)),1))),LEFT(UPPER(TRIM(D7)),1)="X",LEFT(UPPER(TRIM(D7)),1)="Y",LEFT(UPPER(TRIM(D7)),1)="Z"),IF(MID("TRWAGMYFPDXBNJZSQVHLCKE",MOD(VALUE(SUBSTITUTE(SUBSTITUTE(SUBSTITUTE(LEFT(UPPER(TRIM(D7)),8),"X","0"),"Y","1"),"Z","2")),23)+1,1)=RIGHT(UPPER(TRIM(D7)),1),"OK","REVISAR"),IF(OR(RIGHT(UPPER(TRIM(D7)),1)=TEXT(MOD(10-MOD((VALUE(MID(UPPER(TRIM(D7)),3,1))+VALUE(MID(UPPER(TRIM(D7)),5,1))+VALUE(MID(UPPER(TRIM(D7)),7,1)))+(INT(2*VALUE(MID(UPPER(TRIM(D7)),2,1))/10)+MOD(2*VALUE(MID(UPPER(TRIM(D7)),2,1)),10))+(INT(2*VALUE(MID(UPPER(TRIM(D7)),4,1))/10)+MOD(2*VALUE(MID(UPPER(TRIM(D7)),4,1)),10))+(INT(2*VALUE(MID(UPPER(TRIM(D7)),6,1))/10)+MOD(2*VALUE(MID(UPPER(TRIM(D7)),6,1)),10))+(INT(2*VALUE(MID(UPPER(TRIM(D7)),8,1))/10)+MOD(2*VALUE(MID(UPPER(TRIM(D7)),8,1)),10)),10),10),"0"),RIGHT(UPPER(TRIM(D7)),1)=MID("JABCDEFGHI",MOD(10-MOD((VALUE(MID(UPPER(TRIM(D7)),3,1))+VALUE(MID(UPPER(TRIM(D7)),5,1))+VALUE(MID(UPPER(TRIM(D7)),7,1)))+(INT(2*VALUE(MID(UPPER(TRIM(D7)),2,1))/10)+MOD(2*VALUE(MID(UPPER(TRIM(D7)),2,1)),10))+(INT(2*VALUE(MID(UPPER(TRIM(D7)),4,1))/10)+MOD(2*VALUE(MID(UPPER(TRIM(D7)),4,1)),10))+(INT(2*VALUE(MID(UPPER(TRIM(D7)),6,1))/10)+MOD(2*VALUE(MID(UPPER(TRIM(D7)),6,1)),10))+(INT(2*VALUE(MID(UPPER(TRIM(D7)),8,1))/10)+MOD(2*VALUE(MID(UPPER(TRIM(D7)),8,1)),10)),10),10)+1,1)),"OK","REVISAR")),"REVISAR"))) | Q7: =IF(B7="","",IF(COUNTIFS($B$2:$B$501,B7,$D$2:$D$501,D7)>1,"DUPLICADA","")) | R7: =IF(A7="","",ROUNDUP(MONTH(A7)/3,0))
I8: =IF(E8="","",ROUND(E8*0.21,2)) | J8: =IF(F8="","",ROUND(F8*0.1,2)) | K8: =IF(G8="","",ROUND(G8*0.04,2)) | N8: =IF(A8="","",SUM(E8:K8)-N(L8)) | O8: =IF(OR(A8="",M8=""),"",IF(ABS(M8-N8)<=0.02,"OK","REVISAR")) | P8: =IF(D8="","",IF(LEN(TRIM(D8))<>9,"REVISAR",IFERROR(IF(OR(ISNUMBER(VALUE(LEFT(UPPER(TRIM(D8)),1))),LEFT(UPPER(TRIM(D8)),1)="X",LEFT(UPPER(TRIM(D8)),1)="Y",LEFT(UPPER(TRIM(D8)),1)="Z"),IF(MID("TRWAGMYFPDXBNJZSQVHLCKE",MOD(VALUE(SUBSTITUTE(SUBSTITUTE(SUBSTITUTE(LEFT(UPPER(TRIM(D8)),8),"X","0"),"Y","1"),"Z","2")),23)+1,1)=RIGHT(UPPER(TRIM(D8)),1),"OK","REVISAR"),IF(OR(RIGHT(UPPER(TRIM(D8)),1)=TEXT(MOD(10-MOD((VALUE(MID(UPPER(TRIM(D8)),3,1))+VALUE(MID(UPPER(TRIM(D8)),5,1))+VALUE(MID(UPPER(TRIM(D8)),7,1)))+(INT(2*VALUE(MID(UPPER(TRIM(D8)),2,1))/10)+MOD(2*VALUE(MID(UPPER(TRIM(D8)),2,1)),10))+(INT(2*VALUE(MID(UPPER(TRIM(D8)),4,1))/10)+MOD(2*VALUE(MID(UPPER(TRIM(D8)),4,1)),10))+(INT(2*VALUE(MID(UPPER(TRIM(D8)),6,1))/10)+MOD(2*VALUE(MID(UPPER(TRIM(D8)),6,1)),10))+(INT(2*VALUE(MID(UPPER(TRIM(D8)),8,1))/10)+MOD(2*VALUE(MID(UPPER(TRIM(D8)),8,1)),10)),10),10),"0"),RIGHT(UPPER(TRIM(D8)),1)=MID("JABCDEFGHI",MOD(10-MOD((VALUE(MID(UPPER(TRIM(D8)),3,1))+VALUE(MID(UPPER(TRIM(D8)),5,1))+VALUE(MID(UPPER(TRIM(D8)),7,1)))+(INT(2*VALUE(MID(UPPER(TRIM(D8)),2,1))/10)+MOD(2*VALUE(MID(UPPER(TRIM(D8)),2,1)),10))+(INT(2*VALUE(MID(UPPER(TRIM(D8)),4,1))/10)+MOD(2*VALUE(MID(UPPER(TRIM(D8)),4,1)),10))+(INT(2*VALUE(MID(UPPER(TRIM(D8)),6,1))/10)+MOD(2*VALUE(MID(UPPER(TRIM(D8)),6,1)),10))+(INT(2*VALUE(MID(UPPER(TRIM(D8)),8,1))/10)+MOD(2*VALUE(MID(UPPER(TRIM(D8)),8,1)),10)),10),10)+1,1)),"OK","REVISAR")),"REVISAR"))) | Q8: =IF(B8="","",IF(COUNTIFS($B$2:$B$501,B8,$D$2:$D$501,D8)>1,"DUPLICADA","")) | R8: =IF(A8="","",ROUNDUP(MONTH(A8)/3,0))
I9: =IF(E9="","",ROUND(E9*0.21,2)) | J9: =IF(F9="","",ROUND(F9*0.1,2)) | K9: =IF(G9="","",ROUND(G9*0.04,2)) | N9: =IF(A9="","",SUM(E9:K9)-N(L9)) | O9: =IF(OR(A9="",M9=""),"",IF(ABS(M9-N9)<=0.02,"OK","REVISAR")) | P9: =IF(D9="","",IF(LEN(TRIM(D9))<>9,"REVISAR",IFERROR(IF(OR(ISNUMBER(VALUE(LEFT(UPPER(TRIM(D9)),1))),LEFT(UPPER(TRIM(D9)),1)="X",LEFT(UPPER(TRIM(D9)),1)="Y",LEFT(UPPER(TRIM(D9)),1)="Z"),IF(MID("TRWAGMYFPDXBNJZSQVHLCKE",MOD(VALUE(SUBSTITUTE(SUBSTITUTE(SUBSTITUTE(LEFT(UPPER(TRIM(D9)),8),"X","0"),"Y","1"),"Z","2")),23)+1,1)=RIGHT(UPPER(TRIM(D9)),1),"OK","REVISAR"),IF(OR(RIGHT(UPPER(TRIM(D9)),1)=TEXT(MOD(10-MOD((VALUE(MID(UPPER(TRIM(D9)),3,1))+VALUE(MID(UPPER(TRIM(D9)),5,1))+VALUE(MID(UPPER(TRIM(D9)),7,1)))+(INT(2*VALUE(MID(UPPER(TRIM(D9)),2,1))/10)+MOD(2*VALUE(MID(UPPER(TRIM(D9)),2,1)),10))+(INT(2*VALUE(MID(UPPER(TRIM(D9)),4,1))/10)+MOD(2*VALUE(MID(UPPER(TRIM(D9)),4,1)),10))+(INT(2*VALUE(MID(UPPER(TRIM(D9)),6,1))/10)+MOD(2*VALUE(MID(UPPER(TRIM(D9)),6,1)),10))+(INT(2*VALUE(MID(UPPER(TRIM(D9)),8,1))/10)+MOD(2*VALUE(MID(UPPER(TRIM(D9)),8,1)),10)),10),10),"0"),RIGHT(UPPER(TRIM(D9)),1)=MID("JABCDEFGHI",MOD(10-MOD((VALUE(MID(UPPER(TRIM(D9)),3,1))+VALUE(MID(UPPER(TRIM(D9)),5,1))+VALUE(MID(UPPER(TRIM(D9)),7,1)))+(INT(2*VALUE(MID(UPPER(TRIM(D9)),2,1))/10)+MOD(2*VALUE(MID(UPPER(TRIM(D9)),2,1)),10))+(INT(2*VALUE(MID(UPPER(TRIM(D9)),4,1))/10)+MOD(2*VALUE(MID(UPPER(TRIM(D9)),4,1)),10))+(INT(2*VALUE(MID(UPPER(TRIM(D9)),6,1))/10)+MOD(2*VALUE(MID(UPPER(TRIM(D9)),6,1)),10))+(INT(2*VALUE(MID(UPPER(TRIM(D9)),8,1))/10)+MOD(2*VALUE(MID(UPPER(TRIM(D9)),8,1)),10)),10),10)+1,1)),"OK","REVISAR")),"REVISAR"))) | Q9: =IF(B9="","",IF(COUNTIFS($B$2:$B$501,B9,$D$2:$D$501,D9)>1,"DUPLICADA","")) | R9: =IF(A9="","",ROUNDUP(MONTH(A9)/3,0))
I10: =IF(E10="","",ROUND(E10*0.21,2)) | J10: =IF(F10="","",ROUND(F10*0.1,2)) | K10: =IF(G10="","",ROUND(G10*0.04,2)) | N10: =IF(A10="","",SUM(E10:K10)-N(L10)) | O10: =IF(OR(A10="",M10=""),"",IF(ABS(M10-N10)<=0.02,"OK","REVISAR")) | P10: =IF(D10="","",IF(LEN(TRIM(D10))<>9,"REVISAR",IFERROR(IF(OR(ISNUMBER(VALUE(LEFT(UPPER(TRIM(D10)),1))),LEFT(UPPER(TRIM(D10)),1)="X",LEFT(UPPER(TRIM(D10)),1)="Y",LEFT(UPPER(TRIM(D10)),1)="Z"),IF(MID("TRWAGMYFPDXBNJZSQVHLCKE",MOD(VALUE(SUBSTITUTE(SUBSTITUTE(SUBSTITUTE(LEFT(UPPER(TRIM(D10)),8),"X","0"),"Y","1"),"Z","2")),23)+1,1)=RIGHT(UPPER(TRIM(D10)),1),"OK","REVISAR"),IF(OR(RIGHT(UPPER(TRIM(D10)),1)=TEXT(MOD(10-MOD((VALUE(MID(UPPER(TRIM(D10)),3,1))+VALUE(MID(UPPER(TRIM(D10)),5,1))+VALUE(MID(UPPER(TRIM(D10)),7,1)))+(INT(2*VALUE(MID(UPPER(TRIM(D10)),2,1))/10)+MOD(2*VALUE(MID(UPPER(TRIM(D10)),2,1)),10))+(INT(2*VALUE(MID(UPPER(TRIM(D10)),4,1))/10)+MOD(2*VALUE(MID(UPPER(TRIM(D10)),4,1)),10))+(INT(2*VALUE(MID(UPPER(TRIM(D10)),6,1))/10)+MOD(2*VALUE(MID(UPPER(TRIM(D10)),6,1)),10))+(INT(2*VALUE(MID(UPPER(TRIM(D10)),8,1))/10)+MOD(2*VALUE(MID(UPPER(TRIM(D10)),8,1)),10)),10),10),"0"),RIGHT(UPPER(TRIM(D10)),1)=MID("JABCDEFGHI",MOD(10-MOD((VALUE(MID(UPPER(TRIM(D10)),3,1))+VALUE(MID(UPPER(TRIM(D10)),5,1))+VALUE(MID(UPPER(TRIM(D10)),7,1)))+(INT(2*VALUE(MID(UPPER(TRIM(D10)),2,1))/10)+MOD(2*VALUE(MID(UPPER(TRIM(D10)),2,1)),10))+(INT(2*VALUE(MID(UPPER(TRIM(D10)),4,1))/10)+MOD(2*VALUE(MID(UPPER(TRIM(D10)),4,1)),10))+(INT(2*VALUE(MID(UPPER(TRIM(D10)),6,1))/10)+MOD(2*VALUE(MID(UPPER(TRIM(D10)),6,1)),10))+(INT(2*VALUE(MID(UPPER(TRIM(D10)),8,1))/10)+MOD(2*VALUE(MID(UPPER(TRIM(D10)),8,1)),10)),10),10)+1,1)),"OK","REVISAR")),"REVISAR"))) | Q10: =IF(B10="","",IF(COUNTIFS($B$2:$B$501,B10,$D$2:$D$501,D10)>1,"DUPLICADA","")) | R10: =IF(A10="","",ROUNDUP(MONTH(A10)/3,0))
I11: =IF(E11="","",ROUND(E11*0.21,2)) | J11: =IF(F11="","",ROUND(F11*0.1,2)) | K11: =IF(G11="","",ROUND(G11*0.04,2)) | N11: =IF(A11="","",SUM(E11:K11)-N(L11)) | O11: =IF(OR(A11="",M11=""),"",IF(ABS(M11-N11)<=0.02,"OK","REVISAR")) | P11: =IF(D11="","",IF(LEN(TRIM(D11))<>9,"REVISAR",IFERROR(IF(OR(ISNUMBER(VALUE(LEFT(UPPER(TRIM(D11)),1))),LEFT(UPPER(TRIM(D11)),1)="X",LEFT(UPPER(TRIM(D11)),1)="Y",LEFT(UPPER(TRIM(D11)),1)="Z"),IF(MID("TRWAGMYFPDXBNJZSQVHLCKE",MOD(VALUE(SUBSTITUTE(SUBSTITUTE(SUBSTITUTE(LEFT(UPPER(TRIM(D11)),8),"X","0"),"Y","1"),"Z","2")),23)+1,1)=RIGHT(UPPER(TRIM(D11)),1),"OK","REVISAR"),IF(OR(RIGHT(UPPER(TRIM(D11)),1)=TEXT(MOD(10-MOD((VALUE(MID(UPPER(TRIM(D11)),3,1))+VALUE(MID(UPPER(TRIM(D11)),5,1))+VALUE(MID(UPPER(TRIM(D11)),7,1)))+(INT(2*VALUE(MID(UPPER(TRIM(D11)),2,1))/10)+MOD(2*VALUE(MID(UPPER(TRIM(D11)),2,1)),10))+(INT(2*VALUE(MID(UPPER(TRIM(D11)),4,1))/10)+MOD(2*VALUE(MID(UPPER(TRIM(D11)),4,1)),10))+(INT(2*VALUE(MID(UPPER(TRIM(D11)),6,1))/10)+MOD(2*VALUE(MID(UPPER(TRIM(D11)),6,1)),10))+(INT(2*VALUE(MID(UPPER(TRIM(D11)),8,1))/10)+MOD(2*VALUE(MID(UPPER(TRIM(D11)),8,1)),10)),10),10),"0"),RIGHT(UPPER(TRIM(D11)),1)=MID("JABCDEFGHI",MOD(10-MOD((VALUE(MID(UPPER(TRIM(D11)),3,1))+VALUE(MID(UPPER(TRIM(D11)),5,1))+VALUE(MID(UPPER(TRIM(D11)),7,1)))+(INT(2*VALUE(MID(UPPER(TRIM(D11)),2,1))/10)+MOD(2*VALUE(MID(UPPER(TRIM(D11)),2,1)),10))+(INT(2*VALUE(MID(UPPER(TRIM(D11)),4,1))/10)+MOD(2*VALUE(MID(UPPER(TRIM(D11)),4,1)),10))+(INT(2*VALUE(MID(UPPER(TRIM(D11)),6,1))/10)+MOD(2*VALUE(MID(UPPER(TRIM(D11)),6,1)),10))+(INT(2*VALUE(MID(UPPER(TRIM(D11)),8,1))/10)+MOD(2*VALUE(MID(UPPER(TRIM(D11)),8,1)),10)),10),10)+1,1)),"OK","REVISAR")),"REVISAR"))) | Q11: =IF(B11="","",IF(COUNTIFS($B$2:$B$501,B11,$D$2:$D$501,D11)>1,"DUPLICADA","")) | R11: =IF(A11="","",ROUNDUP(MONTH(A11)/3,0))
I12: =IF(E12="","",ROUND(E12*0.21,2)) | J12: =IF(F12="","",ROUND(F12*0.1,2)) | K12: =IF(G12="","",ROUND(G12*0.04,2)) | N12: =IF(A12="","",SUM(E12:K12)-N(L12)) | O12: =IF(OR(A12="",M12=""),"",IF(ABS(M12-N12)<=0.02,"OK","REVISAR")) | P12: =IF(D12="","",IF(LEN(TRIM(D12))<>9,"REVISAR",IFERROR(IF(OR(ISNUMBER(VALUE(LEFT(UPPER(TRIM(D12)),1))),LEFT(UPPER(TRIM(D12)),1)="X",LEFT(UPPER(TRIM(D12)),1)="Y",LEFT(UPPER(TRIM(D12)),1)="Z"),IF(MID("TRWAGMYFPDXBNJZSQVHLCKE",MOD(VALUE(SUBSTITUTE(SUBSTITUTE(SUBSTITUTE(LEFT(UPPER(TRIM(D12)),8),"X","0"),"Y","1"),"Z","2")),23)+1,1)=RIGHT(UPPER(TRIM(D12)),1),"OK","REVISAR"),IF(OR(RIGHT(UPPER(TRIM(D12)),1)=TEXT(MOD(10-MOD((VALUE(MID(UPPER(TRIM(D12)),3,1))+VALUE(MID(UPPER(TRIM(D12)),5,1))+VALUE(MID(UPPER(TRIM(D12)),7,1)))+(INT(2*VALUE(MID(UPPER(TRIM(D12)),2,1))/10)+MOD(2*VALUE(MID(UPPER(TRIM(D12)),2,1)),10))+(INT(2*VALUE(MID(UPPER(TRIM(D12)),4,1))/10)+MOD(2*VALUE(MID(UPPER(TRIM(D12)),4,1)),10))+(INT(2*VALUE(MID(UPPER(TRIM(D12)),6,1))/10)+MOD(2*VALUE(MID(UPPER(TRIM(D12)),6,1)),10))+(INT(2*VALUE(MID(UPPER(TRIM(D12)),8,1))/10)+MOD(2*VALUE(MID(UPPER(TRIM(D12)),8,1)),10)),10),10),"0"),RIGHT(UPPER(TRIM(D12)),1)=MID("JABCDEFGHI",MOD(10-MOD((VALUE(MID(UPPER(TRIM(D12)),3,1))+VALUE(MID(UPPER(TRIM(D12)),5,1))+VALUE(MID(UPPER(TRIM(D12)),7,1)))+(INT(2*VALUE(MID(UPPER(TRIM(D12)),2,1))/10)+MOD(2*VALUE(MID(UPPER(TRIM(D12)),2,1)),10))+(INT(2*VALUE(MID(UPPER(TRIM(D12)),4,1))/10)+MOD(2*VALUE(MID(UPPER(TRIM(D12)),4,1)),10))+(INT(2*VALUE(MID(UPPER(TRIM(D12)),6,1))/10)+MOD(2*VALUE(MID(UPPER(TRIM(D12)),6,1)),10))+(INT(2*VALUE(MID(UPPER(TRIM(D12)),8,1))/10)+MOD(2*VALUE(MID(UPPER(TRIM(D12)),8,1)),10)),10),10)+1,1)),"OK","REVISAR")),"REVISAR"))) | Q12: =IF(B12="","",IF(COUNTIFS($B$2:$B$501,B12,$D$2:$D$501,D12)>1,"DUPLICADA","")) | R12: =IF(A12="","",ROUNDUP(MONTH(A12)/3,0))
I13: =IF(E13="","",ROUND(E13*0.21,2)) | J13: =IF(F13="","",ROUND(F13*0.1,2)) | K13: =IF(G13="","",ROUND(G13*0.04,2)) | N13: =IF(A13="","",SUM(E13:K13)-N(L13)) | O13: =IF(OR(A13="",M13=""),"",IF(ABS(M13-N13)<=0.02,"OK","REVISAR")) | P13: =IF(D13="","",IF(LEN(TRIM(D13))<>9,"REVISAR",IFERROR(IF(OR(ISNUMBER(VALUE(LEFT(UPPER(TRIM(D13)),1))),LEFT(UPPER(TRIM(D13)),1)="X",LEFT(UPPER(TRIM(D13)),1)="Y",LEFT(UPPER(TRIM(D13)),1)="Z"),IF(MID("TRWAGMYFPDXBNJZSQVHLCKE",MOD(VALUE(SUBSTITUTE(SUBSTITUTE(SUBSTITUTE(LEFT(UPPER(TRIM(D13)),8),"X","0"),"Y","1"),"Z","2")),23)+1,1)=RIGHT(UPPER(TRIM(D13)),1),"OK","REVISAR"),IF(OR(RIGHT(UPPER(TRIM(D13)),1)=TEXT(MOD(10-MOD((VALUE(MID(UPPER(TRIM(D13)),3,1))+VALUE(MID(UPPER(TRIM(D13)),5,1))+VALUE(MID(UPPER(TRIM(D13)),7,1)))+(INT(2*VALUE(MID(UPPER(TRIM(D13)),2,1))/10)+MOD(2*VALUE(MID(UPPER(TRIM(D13)),2,1)),10))+(INT(2*VALUE(MID(UPPER(TRIM(D13)),4,1))/10)+MOD(2*VALUE(MID(UPPER(TRIM(D13)),4,1)),10))+(INT(2*VALUE(MID(UPPER(TRIM(D13)),6,1))/10)+MOD(2*VALUE(MID(UPPER(TRIM(D13)),6,1)),10))+(INT(2*VALUE(MID(UPPER(TRIM(D13)),8,1))/10)+MOD(2*VALUE(MID(UPPER(TRIM(D13)),8,1)),10)),10),10),"0"),RIGHT(UPPER(TRIM(D13)),1)=MID("JABCDEFGHI",MOD(10-MOD((VALUE(MID(UPPER(TRIM(D13)),3,1))+VALUE(MID(UPPER(TRIM(D13)),5,1))+VALUE(MID(UPPER(TRIM(D13)),7,1)))+(INT(2*VALUE(MID(UPPER(TRIM(D13)),2,1))/10)+MOD(2*VALUE(MID(UPPER(TRIM(D13)),2,1)),10))+(INT(2*VALUE(MID(UPPER(TRIM(D13)),4,1))/10)+MOD(2*VALUE(MID(UPPER(TRIM(D13)),4,1)),10))+(INT(2*VALUE(MID(UPPER(TRIM(D13)),6,1))/10)+MOD(2*VALUE(MID(UPPER(TRIM(D13)),6,1)),10))+(INT(2*VALUE(MID(UPPER(TRIM(D13)),8,1))/10)+MOD(2*VALUE(MID(UPPER(TRIM(D13)),8,1)),10)),10),10)+1,1)),"OK","REVISAR")),"REVISAR"))) | Q13: =IF(B13="","",IF(COUNTIFS($B$2:$B$501,B13,$D$2:$D$501,D13)>1,"DUPLICADA","")) | R13: =IF(A13="","",ROUNDUP(MONTH(A13)/3,0))
I14: =IF(E14="","",ROUND(E14*0.21,2)) | J14: =IF(F14="","",ROUND(F14*0.1,2)) | K14: =IF(G14="","",ROUND(G14*0.04,2)) | N14: =IF(A14="","",SUM(E14:K14)-N(L14)) | O14: =IF(OR(A14="",M14=""),"",IF(ABS(M14-N14)<=0.02,"OK","REVISAR")) | P14: =IF(D14="","",IF(LEN(TRIM(D14))<>9,"REVISAR",IFERROR(IF(OR(ISNUMBER(VALUE(LEFT(UPPER(TRIM(D14)),1))),LEFT(UPPER(TRIM(D14)),1)="X",LEFT(UPPER(TRIM(D14)),1)="Y",LEFT(UPPER(TRIM(D14)),1)="Z"),IF(MID("TRWAGMYFPDXBNJZSQVHLCKE",MOD(VALUE(SUBSTITUTE(SUBSTITUTE(SUBSTITUTE(LEFT(UPPER(TRIM(D14)),8),"X","0"),"Y","1"),"Z","2")),23)+1,1)=RIGHT(UPPER(TRIM(D14)),1),"OK","REVISAR"),IF(OR(RIGHT(UPPER(TRIM(D14)),1)=TEXT(MOD(10-MOD((VALUE(MID(UPPER(TRIM(D14)),3,1))+VALUE(MID(UPPER(TRIM(D14)),5,1))+VALUE(MID(UPPER(TRIM(D14)),7,1)))+(INT(2*VALUE(MID(UPPER(TRIM(D14)),2,1))/10)+MOD(2*VALUE(MID(UPPER(TRIM(D14)),2,1)),10))+(INT(2*VALUE(MID(UPPER(TRIM(D14)),4,1))/10)+MOD(2*VALUE(MID(UPPER(TRIM(D14)),4,1)),10))+(INT(2*VALUE(MID(UPPER(TRIM(D14)),6,1))/10)+MOD(2*VALUE(MID(UPPER(TRIM(D14)),6,1)),10))+(INT(2*VALUE(MID(UPPER(TRIM(D14)),8,1))/10)+MOD(2*VALUE(MID(UPPER(TRIM(D14)),8,1)),10)),10),10),"0"),RIGHT(UPPER(TRIM(D14)),1)=MID("JABCDEFGHI",MOD(10-MOD((VALUE(MID(UPPER(TRIM(D14)),3,1))+VALUE(MID(UPPER(TRIM(D14)),5,1))+VALUE(MID(UPPER(TRIM(D14)),7,1)))+(INT(2*VALUE(MID(UPPER(TRIM(D14)),2,1))/10)+MOD(2*VALUE(MID(UPPER(TRIM(D14)),2,1)),10))+(INT(2*VALUE(MID(UPPER(TRIM(D14)),4,1))/10)+MOD(2*VALUE(MID(UPPER(TRIM(D14)),4,1)),10))+(INT(2*VALUE(MID(UPPER(TRIM(D14)),6,1))/10)+MOD(2*VALUE(MID(UPPER(TRIM(D14)),6,1)),10))+(INT(2*VALUE(MID(UPPER(TRIM(D14)),8,1))/10)+MOD(2*VALUE(MID(UPPER(TRIM(D14)),8,1)),10)),10),10)+1,1)),"OK","REVISAR")),"REVISAR"))) | Q14: =IF(B14="","",IF(COUNTIFS($B$2:$B$501,B14,$D$2:$D$501,D14)>1,"DUPLICADA","")) | R14: =IF(A14="","",ROUNDUP(MONTH(A14)/3,0))
I15: =IF(E15="","",ROUND(E15*0.21,2)) | J15: =IF(F15="","",ROUND(F15*0.1,2)) | K15: =IF(G15="","",ROUND(G15*0.04,2)) | N15: =IF(A15="","",SUM(E15:K15)-N(L15)) | O15: =IF(OR(A15="",M15=""),"",IF(ABS(M15-N15)<=0.02,"OK","REVISAR")) | P15: =IF(D15="","",IF(LEN(TRIM(D15))<>9,"REVISAR",IFERROR(IF(OR(ISNUMBER(VALUE(LEFT(UPPER(TRIM(D15)),1))),LEFT(UPPER(TRIM(D15)),1)="X",LEFT(UPPER(TRIM(D15)),1)="Y",LEFT(UPPER(TRIM(D15)),1)="Z"),IF(MID("TRWAGMYFPDXBNJZSQVHLCKE",MOD(VALUE(SUBSTITUTE(SUBSTITUTE(SUBSTITUTE(LEFT(UPPER(TRIM(D15)),8),"X","0"),"Y","1"),"Z","2")),23)+1,1)=RIGHT(UPPER(TRIM(D15)),1),"OK","REVISAR"),IF(OR(RIGHT(UPPER(TRIM(D15)),1)=TEXT(MOD(10-MOD((VALUE(MID(UPPER(TRIM(D15)),3,1))+VALUE(MID(UPPER(TRIM(D15)),5,1))+VALUE(MID(UPPER(TRIM(D15)),7,1)))+(INT(2*VALUE(MID(UPPER(TRIM(D15)),2,1))/10)+MOD(2*VALUE(MID(UPPER(TRIM(D15)),2,1)),10))+(INT(2*VALUE(MID(UPPER(TRIM(D15)),4,1))/10)+MOD(2*VALUE(MID(UPPER(TRIM(D15)),4,1)),10))+(INT(2*VALUE(MID(UPPER(TRIM(D15)),6,1))/10)+MOD(2*VALUE(MID(UPPER(TRIM(D15)),6,1)),10))+(INT(2*VALUE(MID(UPPER(TRIM(D15)),8,1))/10)+MOD(2*VALUE(MID(UPPER(TRIM(D15)),8,1)),10)),10),10),"0"),RIGHT(UPPER(TRIM(D15)),1)=MID("JABCDEFGHI",MOD(10-MOD((VALUE(MID(UPPER(TRIM(D15)),3,1))+VALUE(MID(UPPER(TRIM(D15)),5,1))+VALUE(MID(UPPER(TRIM(D15)),7,1)))+(INT(2*VALUE(MID(UPPER(TRIM(D15)),2,1))/10)+MOD(2*VALUE(MID(UPPER(TRIM(D15)),2,1)),10))+(INT(2*VALUE(MID(UPPER(TRIM(D15)),4,1))/10)+MOD(2*VALUE(MID(UPPER(TRIM(D15)),4,1)),10))+(INT(2*VALUE(MID(UPPER(TRIM(D15)),6,1))/10)+MOD(2*VALUE(MID(UPPER(TRIM(D15)),6,1)),10))+(INT(2*VALUE(MID(UPPER(TRIM(D15)),8,1))/10)+MOD(2*VALUE(MID(UPPER(TRIM(D15)),8,1)),10)),10),10)+1,1)),"OK","REVISAR")),"REVISAR"))) | Q15: =IF(B15="","",IF(COUNTIFS($B$2:$B$501,B15,$D$2:$D$501,D15)>1,"DUPLICADA","")) | R15: =IF(A15="","",ROUNDUP(MONTH(A15)/3,0))
I16: =IF(E16="","",ROUND(E16*0.21,2)) | J16: =IF(F16="","",ROUND(F16*0.1,2)) | K16: =IF(G16="","",ROUND(G16*0.04,2)) | N16: =IF(A16="","",SUM(E16:K16)-N(L16)) | O16: =IF(OR(A16="",M16=""),"",IF(ABS(M16-N16)<=0.02,"OK","REVISAR")) | P16: =IF(D16="","",IF(LEN(TRIM(D16))<>9,"REVISAR",IFERROR(IF(OR(ISNUMBER(VALUE(LEFT(UPPER(TRIM(D16)),1))),LEFT(UPPER(TRIM(D16)),1)="X",LEFT(UPPER(TRIM(D16)),1)="Y",LEFT(UPPER(TRIM(D16)),1)="Z"),IF(MID("TRWAGMYFPDXBNJZSQVHLCKE",MOD(VALUE(SUBSTITUTE(SUBSTITUTE(SUBSTITUTE(LEFT(UPPER(TRIM(D16)),8),"X","0"),"Y","1"),"Z","2")),23)+1,1)=RIGHT(UPPER(TRIM(D16)),1),"OK","REVISAR"),IF(OR(RIGHT(UPPER(TRIM(D16)),1)=TEXT(MOD(10-MOD((VALUE(MID(UPPER(TRIM(D16)),3,1))+VALUE(MID(UPPER(TRIM(D16)),5,1))+VALUE(MID(UPPER(TRIM(D16)),7,1)))+(INT(2*VALUE(MID(UPPER(TRIM(D16)),2,1))/10)+MOD(2*VALUE(MID(UPPER(TRIM(D16)),2,1)),10))+(INT(2*VALUE(MID(UPPER(TRIM(D16)),4,1))/10)+MOD(2*VALUE(MID(UPPER(TRIM(D16)),4,1)),10))+(INT(2*VALUE(MID(UPPER(TRIM(D16)),6,1))/10)+MOD(2*VALUE(MID(UPPER(TRIM(D16)),6,1)),10))+(INT(2*VALUE(MID(UPPER(TRIM(D16)),8,1))/10)+MOD(2*VALUE(MID(UPPER(TRIM(D16)),8,1)),10)),10),10),"0"),RIGHT(UPPER(TRIM(D16)),1)=MID("JABCDEFGHI",MOD(10-MOD((VALUE(MID(UPPER(TRIM(D16)),3,1))+VALUE(MID(UPPER(TRIM(D16)),5,1))+VALUE(MID(UPPER(TRIM(D16)),7,1)))+(INT(2*VALUE(MID(UPPER(TRIM(D16)),2,1))/10)+MOD(2*VALUE(MID(UPPER(TRIM(D16)),2,1)),10))+(INT(2*VALUE(MID(UPPER(TRIM(D16)),4,1))/10)+MOD(2*VALUE(MID(UPPER(TRIM(D16)),4,1)),10))+(INT(2*VALUE(MID(UPPER(TRIM(D16)),6,1))/10)+MOD(2*VALUE(MID(UPPER(TRIM(D16)),6,1)),10))+(INT(2*VALUE(MID(UPPER(TRIM(D16)),8,1))/10)+MOD(2*VALUE(MID(UPPER(TRIM(D16)),8,1)),10)),10),10)+1,1)),"OK","REVISAR")),"REVISAR"))) | Q16: =IF(B16="","",IF(COUNTIFS($B$2:$B$501,B16,$D$2:$D$501,D16)>1,"DUPLICADA","")) | R16: =IF(A16="","",ROUNDUP(MONTH(A16)/3,0))
... I501: =IF(E501="","",ROUND(E501*0.21,2)) | J501: =IF(F501="","",ROUND(F501*0.1,2)) | K501: =IF(G501="","",ROUND(G501*0.04,2)) | N501: =IF(A501="","",SUM(E501:K501)-N(L501)) | O501: =IF(OR(A501="",M501=""),"",IF(ABS(M501-N501)<=0.02,"OK","REVISAR")) | P501: =IF(D501="","",IF(LEN(TRIM(D501))<>9,"REVISAR",IFERROR(IF(OR(ISNUMBER(VALUE(LEFT(UPPER(TRIM(D501)),1))),LEFT(UPPER(TRIM(D501)),1)="X",LEFT(UPPER(TRIM(D501)),1)="Y",LEFT(UPPER(TRIM(D501)),1)="Z"),IF(MID("TRWAGMYFPDXBNJZSQVHLCKE",MOD(VALUE(SUBSTITUTE(SUBSTITUTE(SUBSTITUTE(LEFT(UPPER(TRIM(D501)),8),"X","0"),"Y","1"),"Z","2")),23)+1,1)=RIGHT(UPPER(TRIM(D501)),1),"OK","REVISAR"),IF(OR(RIGHT(UPPER(TRIM(D501)),1)=TEXT(MOD(10-MOD((VALUE(MID(UPPER(TRIM(D501)),3,1))+VALUE(MID(UPPER(TRIM(D501)),5,1))+VALUE(MID(UPPER(TRIM(D501)),7,1)))+(INT(2*VALUE(MID(UPPER(TRIM(D501)),2,1))/10)+MOD(2*VALUE(MID(UPPER(TRIM(D501)),2,1)),10))+(INT(2*VALUE(MID(UPPER(TRIM(D501)),4,1))/10)+MOD(2*VALUE(MID(UPPER(TRIM(D501)),4,1)),10))+(INT(2*VALUE(MID(UPPER(TRIM(D501)),6,1))/10)+MOD(2*VALUE(MID(UPPER(TRIM(D501)),6,1)),10))+(INT(2*VALUE(MID(UPPER(TRIM(D501)),8,1))/10)+MOD(2*VALUE(MID(UPPER(TRIM(D501)),8,1)),10)),10),10),"0"),RIGHT(UPPER(TRIM(D501)),1)=MID("JABCDEFGHI",MOD(10-MOD((VALUE(MID(UPPER(TRIM(D501)),3,1))+VALUE(MID(UPPER(TRIM(D501)),5,1))+VALUE(MID(UPPER(TRIM(D501)),7,1)))+(INT(2*VALUE(MID(UPPER(TRIM(D501)),2,1))/10)+MOD(2*VALUE(MID(UPPER(TRIM(D501)),2,1)),10))+(INT(2*VALUE(MID(UPPER(TRIM(D501)),4,1))/10)+MOD(2*VALUE(MID(UPPER(TRIM(D501)),4,1)),10))+(INT(2*VALUE(MID(UPPER(TRIM(D501)),6,1))/10)+MOD(2*VALUE(MID(UPPER(TRIM(D501)),6,1)),10))+(INT(2*VALUE(MID(UPPER(TRIM(D501)),8,1))/10)+MOD(2*VALUE(MID(UPPER(TRIM(D501)),8,1)),10)),10),10)+1,1)),"OK","REVISAR")),"REVISAR"))) | Q501: =IF(B501="","",IF(COUNTIFS($B$2:$B$501,B501,$D$2:$D$501,D501)>1,"DUPLICADA","")) | R501: =IF(A501="","",ROUNDUP(MONTH(A501)/3,0))

Sheet Recibidas
A1: Fecha | B1: N.º factura | C1: Proveedor | D1: NIF | E1: Base 21 % | F1: Base 10 % | G1: Base 4 % | H1: Base exenta o 0 % | I1: Cuota 21 % | J1: Cuota 10 % | K1: Cuota 4 % | L1: Retención IRPF | M1: Total en la factura | N1: Total calculado | O1: ¿Cuadra? | P1: ¿NIF válido? | Q1: ¿Duplicada? | R1: Trimestre | S1: Cuenta PGC
A2: 46205 | B2: A-1187 | C2: Suministros Ejemplo, S.L. | D2: B12345674 | E2: 412.4 | I2: =IF(E2="","",ROUND(E2*0.21,2)) | J2: =IF(F2="","",ROUND(F2*0.1,2)) | K2: =IF(G2="","",ROUND(G2*0.04,2)) | M2: 499 | N2: =IF(A2="","",SUM(E2:K2)-N(L2)) | O2: =IF(OR(A2="",M2=""),"",IF(ABS(M2-N2)<=0.02,"OK","REVISAR")) | P2: =IF(D2="","",IF(LEN(TRIM(D2))<>9,"REVISAR",IFERROR(IF(OR(ISNUMBER(VALUE(LEFT(UPPER(TRIM(D2)),1))),LEFT(UPPER(TRIM(D2)),1)="X",LEFT(UPPER(TRIM(D2)),1)="Y",LEFT(UPPER(TRIM(D2)),1)="Z"),IF(MID("TRWAGMYFPDXBNJZSQVHLCKE",MOD(VALUE(SUBSTITUTE(SUBSTITUTE(SUBSTITUTE(LEFT(UPPER(TRIM(D2)),8),"X","0"),"Y","1"),"Z","2")),23)+1,1)=RIGHT(UPPER(TRIM(D2)),1),"OK","REVISAR"),IF(OR(RIGHT(UPPER(TRIM(D2)),1)=TEXT(MOD(10-MOD((VALUE(MID(UPPER(TRIM(D2)),3,1))+VALUE(MID(UPPER(TRIM(D2)),5,1))+VALUE(MID(UPPER(TRIM(D2)),7,1)))+(INT(2*VALUE(MID(UPPER(TRIM(D2)),2,1))/10)+MOD(2*VALUE(MID(UPPER(TRIM(D2)),2,1)),10))+(INT(2*VALUE(MID(UPPER(TRIM(D2)),4,1))/10)+MOD(2*VALUE(MID(UPPER(TRIM(D2)),4,1)),10))+(INT(2*VALUE(MID(UPPER(TRIM(D2)),6,1))/10)+MOD(2*VALUE(MID(UPPER(TRIM(D2)),6,1)),10))+(INT(2*VALUE(MID(UPPER(TRIM(D2)),8,1))/10)+MOD(2*VALUE(MID(UPPER(TRIM(D2)),8,1)),10)),10),10),"0"),RIGHT(UPPER(TRIM(D2)),1)=MID("JABCDEFGHI",MOD(10-MOD((VALUE(MID(UPPER(TRIM(D2)),3,1))+VALUE(MID(UPPER(TRIM(D2)),5,1))+VALUE(MID(UPPER(TRIM(D2)),7,1)))+(INT(2*VALUE(MID(UPPER(TRIM(D2)),2,1))/10)+MOD(2*VALUE(MID(UPPER(TRIM(D2)),2,1)),10))+(INT(2*VALUE(MID(UPPER(TRIM(D2)),4,1))/10)+MOD(2*VALUE(MID(UPPER(TRIM(D2)),4,1)),10))+(INT(2*VALUE(MID(UPPER(TRIM(D2)),6,1))/10)+MOD(2*VALUE(MID(UPPER(TRIM(D2)),6,1)),10))+(INT(2*VALUE(MID(UPPER(TRIM(D2)),8,1))/10)+MOD(2*VALUE(MID(UPPER(TRIM(D2)),8,1)),10)),10),10)+1,1)),"OK","REVISAR")),"REVISAR"))) | Q2: =IF(B2="","",IF(COUNTIFS($B$2:$B$501,B2,$D$2:$D$501,D2)>1,"DUPLICADA","")) | R2: =IF(A2="","",ROUNDUP(MONTH(A2)/3,0)) | S2: 602
A3: 46249 | B3: 2026/311 | C3: Asesor Ejemplo | D3: 12345678Z | E3: 300 | I3: =IF(E3="","",ROUND(E3*0.21,2)) | J3: =IF(F3="","",ROUND(F3*0.1,2)) | K3: =IF(G3="","",ROUND(G3*0.04,2)) | L3: 45 | M3: 318 | N3: =IF(A3="","",SUM(E3:K3)-N(L3)) | O3: =IF(OR(A3="",M3=""),"",IF(ABS(M3-N3)<=0.02,"OK","REVISAR")) | P3: =IF(D3="","",IF(LEN(TRIM(D3))<>9,"REVISAR",IFERROR(IF(OR(ISNUMBER(VALUE(LEFT(UPPER(TRIM(D3)),1))),LEFT(UPPER(TRIM(D3)),1)="X",LEFT(UPPER(TRIM(D3)),1)="Y",LEFT(UPPER(TRIM(D3)),1)="Z"),IF(MID("TRWAGMYFPDXBNJZSQVHLCKE",MOD(VALUE(SUBSTITUTE(SUBSTITUTE(SUBSTITUTE(LEFT(UPPER(TRIM(D3)),8),"X","0"),"Y","1"),"Z","2")),23)+1,1)=RIGHT(UPPER(TRIM(D3)),1),"OK","REVISAR"),IF(OR(RIGHT(UPPER(TRIM(D3)),1)=TEXT(MOD(10-MOD((VALUE(MID(UPPER(TRIM(D3)),3,1))+VALUE(MID(UPPER(TRIM(D3)),5,1))+VALUE(MID(UPPER(TRIM(D3)),7,1)))+(INT(2*VALUE(MID(UPPER(TRIM(D3)),2,1))/10)+MOD(2*VALUE(MID(UPPER(TRIM(D3)),2,1)),10))+(INT(2*VALUE(MID(UPPER(TRIM(D3)),4,1))/10)+MOD(2*VALUE(MID(UPPER(TRIM(D3)),4,1)),10))+(INT(2*VALUE(MID(UPPER(TRIM(D3)),6,1))/10)+MOD(2*VALUE(MID(UPPER(TRIM(D3)),6,1)),10))+(INT(2*VALUE(MID(UPPER(TRIM(D3)),8,1))/10)+MOD(2*VALUE(MID(UPPER(TRIM(D3)),8,1)),10)),10),10),"0"),RIGHT(UPPER(TRIM(D3)),1)=MID("JABCDEFGHI",MOD(10-MOD((VALUE(MID(UPPER(TRIM(D3)),3,1))+VALUE(MID(UPPER(TRIM(D3)),5,1))+VALUE(MID(UPPER(TRIM(D3)),7,1)))+(INT(2*VALUE(MID(UPPER(TRIM(D3)),2,1))/10)+MOD(2*VALUE(MID(UPPER(TRIM(D3)),2,1)),10))+(INT(2*VALUE(MID(UPPER(TRIM(D3)),4,1))/10)+MOD(2*VALUE(MID(UPPER(TRIM(D3)),4,1)),10))+(INT(2*VALUE(MID(UPPER(TRIM(D3)),6,1))/10)+MOD(2*VALUE(MID(UPPER(TRIM(D3)),6,1)),10))+(INT(2*VALUE(MID(UPPER(TRIM(D3)),8,1))/10)+MOD(2*VALUE(MID(UPPER(TRIM(D3)),8,1)),10)),10),10)+1,1)),"OK","REVISAR")),"REVISAR"))) | Q3: =IF(B3="","",IF(COUNTIFS($B$2:$B$501,B3,$D$2:$D$501,D3)>1,"DUPLICADA","")) | R3: =IF(A3="","",ROUNDUP(MONTH(A3)/3,0)) | S3: 623
A4: 46293 | B4: F-77 | C4: Restaurante Ejemplo | D4: B12345675 | F4: 54.55 | I4: =IF(E4="","",ROUND(E4*0.21,2)) | J4: =IF(F4="","",ROUND(F4*0.1,2)) | K4: =IF(G4="","",ROUND(G4*0.04,2)) | M4: 60.01 | N4: =IF(A4="","",SUM(E4:K4)-N(L4)) | O4: =IF(OR(A4="",M4=""),"",IF(ABS(M4-N4)<=0.02,"OK","REVISAR")) | P4: =IF(D4="","",IF(LEN(TRIM(D4))<>9,"REVISAR",IFERROR(IF(OR(ISNUMBER(VALUE(LEFT(UPPER(TRIM(D4)),1))),LEFT(UPPER(TRIM(D4)),1)="X",LEFT(UPPER(TRIM(D4)),1)="Y",LEFT(UPPER(TRIM(D4)),1)="Z"),IF(MID("TRWAGMYFPDXBNJZSQVHLCKE",MOD(VALUE(SUBSTITUTE(SUBSTITUTE(SUBSTITUTE(LEFT(UPPER(TRIM(D4)),8),"X","0"),"Y","1"),"Z","2")),23)+1,1)=RIGHT(UPPER(TRIM(D4)),1),"OK","REVISAR"),IF(OR(RIGHT(UPPER(TRIM(D4)),1)=TEXT(MOD(10-MOD((VALUE(MID(UPPER(TRIM(D4)),3,1))+VALUE(MID(UPPER(TRIM(D4)),5,1))+VALUE(MID(UPPER(TRIM(D4)),7,1)))+(INT(2*VALUE(MID(UPPER(TRIM(D4)),2,1))/10)+MOD(2*VALUE(MID(UPPER(TRIM(D4)),2,1)),10))+(INT(2*VALUE(MID(UPPER(TRIM(D4)),4,1))/10)+MOD(2*VALUE(MID(UPPER(TRIM(D4)),4,1)),10))+(INT(2*VALUE(MID(UPPER(TRIM(D4)),6,1))/10)+MOD(2*VALUE(MID(UPPER(TRIM(D4)),6,1)),10))+(INT(2*VALUE(MID(UPPER(TRIM(D4)),8,1))/10)+MOD(2*VALUE(MID(UPPER(TRIM(D4)),8,1)),10)),10),10),"0"),RIGHT(UPPER(TRIM(D4)),1)=MID("JABCDEFGHI",MOD(10-MOD((VALUE(MID(UPPER(TRIM(D4)),3,1))+VALUE(MID(UPPER(TRIM(D4)),5,1))+VALUE(MID(UPPER(TRIM(D4)),7,1)))+(INT(2*VALUE(MID(UPPER(TRIM(D4)),2,1))/10)+MOD(2*VALUE(MID(UPPER(TRIM(D4)),2,1)),10))+(INT(2*VALUE(MID(UPPER(TRIM(D4)),4,1))/10)+MOD(2*VALUE(MID(UPPER(TRIM(D4)),4,1)),10))+(INT(2*VALUE(MID(UPPER(TRIM(D4)),6,1))/10)+MOD(2*VALUE(MID(UPPER(TRIM(D4)),6,1)),10))+(INT(2*VALUE(MID(UPPER(TRIM(D4)),8,1))/10)+MOD(2*VALUE(MID(UPPER(TRIM(D4)),8,1)),10)),10),10)+1,1)),"OK","REVISAR")),"REVISAR"))) | Q4: =IF(B4="","",IF(COUNTIFS($B$2:$B$501,B4,$D$2:$D$501,D4)>1,"DUPLICADA","")) | R4: =IF(A4="","",ROUNDUP(MONTH(A4)/3,0)) | S4: 629
I5: =IF(E5="","",ROUND(E5*0.21,2)) | J5: =IF(F5="","",ROUND(F5*0.1,2)) | K5: =IF(G5="","",ROUND(G5*0.04,2)) | N5: =IF(A5="","",SUM(E5:K5)-N(L5)) | O5: =IF(OR(A5="",M5=""),"",IF(ABS(M5-N5)<=0.02,"OK","REVISAR")) | P5: =IF(D5="","",IF(LEN(TRIM(D5))<>9,"REVISAR",IFERROR(IF(OR(ISNUMBER(VALUE(LEFT(UPPER(TRIM(D5)),1))),LEFT(UPPER(TRIM(D5)),1)="X",LEFT(UPPER(TRIM(D5)),1)="Y",LEFT(UPPER(TRIM(D5)),1)="Z"),IF(MID("TRWAGMYFPDXBNJZSQVHLCKE",MOD(VALUE(SUBSTITUTE(SUBSTITUTE(SUBSTITUTE(LEFT(UPPER(TRIM(D5)),8),"X","0"),"Y","1"),"Z","2")),23)+1,1)=RIGHT(UPPER(TRIM(D5)),1),"OK","REVISAR"),IF(OR(RIGHT(UPPER(TRIM(D5)),1)=TEXT(MOD(10-MOD((VALUE(MID(UPPER(TRIM(D5)),3,1))+VALUE(MID(UPPER(TRIM(D5)),5,1))+VALUE(MID(UPPER(TRIM(D5)),7,1)))+(INT(2*VALUE(MID(UPPER(TRIM(D5)),2,1))/10)+MOD(2*VALUE(MID(UPPER(TRIM(D5)),2,1)),10))+(INT(2*VALUE(MID(UPPER(TRIM(D5)),4,1))/10)+MOD(2*VALUE(MID(UPPER(TRIM(D5)),4,1)),10))+(INT(2*VALUE(MID(UPPER(TRIM(D5)),6,1))/10)+MOD(2*VALUE(MID(UPPER(TRIM(D5)),6,1)),10))+(INT(2*VALUE(MID(UPPER(TRIM(D5)),8,1))/10)+MOD(2*VALUE(MID(UPPER(TRIM(D5)),8,1)),10)),10),10),"0"),RIGHT(UPPER(TRIM(D5)),1)=MID("JABCDEFGHI",MOD(10-MOD((VALUE(MID(UPPER(TRIM(D5)),3,1))+VALUE(MID(UPPER(TRIM(D5)),5,1))+VALUE(MID(UPPER(TRIM(D5)),7,1)))+(INT(2*VALUE(MID(UPPER(TRIM(D5)),2,1))/10)+MOD(2*VALUE(MID(UPPER(TRIM(D5)),2,1)),10))+(INT(2*VALUE(MID(UPPER(TRIM(D5)),4,1))/10)+MOD(2*VALUE(MID(UPPER(TRIM(D5)),4,1)),10))+(INT(2*VALUE(MID(UPPER(TRIM(D5)),6,1))/10)+MOD(2*VALUE(MID(UPPER(TRIM(D5)),6,1)),10))+(INT(2*VALUE(MID(UPPER(TRIM(D5)),8,1))/10)+MOD(2*VALUE(MID(UPPER(TRIM(D5)),8,1)),10)),10),10)+1,1)),"OK","REVISAR")),"REVISAR"))) | Q5: =IF(B5="","",IF(COUNTIFS($B$2:$B$501,B5,$D$2:$D$501,D5)>1,"DUPLICADA","")) | R5: =IF(A5="","",ROUNDUP(MONTH(A5)/3,0))
I6: =IF(E6="","",ROUND(E6*0.21,2)) | J6: =IF(F6="","",ROUND(F6*0.1,2)) | K6: =IF(G6="","",ROUND(G6*0.04,2)) | N6: =IF(A6="","",SUM(E6:K6)-N(L6)) | O6: =IF(OR(A6="",M6=""),"",IF(ABS(M6-N6)<=0.02,"OK","REVISAR")) | P6: =IF(D6="","",IF(LEN(TRIM(D6))<>9,"REVISAR",IFERROR(IF(OR(ISNUMBER(VALUE(LEFT(UPPER(TRIM(D6)),1))),LEFT(UPPER(TRIM(D6)),1)="X",LEFT(UPPER(TRIM(D6)),1)="Y",LEFT(UPPER(TRIM(D6)),1)="Z"),IF(MID("TRWAGMYFPDXBNJZSQVHLCKE",MOD(VALUE(SUBSTITUTE(SUBSTITUTE(SUBSTITUTE(LEFT(UPPER(TRIM(D6)),8),"X","0"),"Y","1"),"Z","2")),23)+1,1)=RIGHT(UPPER(TRIM(D6)),1),"OK","REVISAR"),IF(OR(RIGHT(UPPER(TRIM(D6)),1)=TEXT(MOD(10-MOD((VALUE(MID(UPPER(TRIM(D6)),3,1))+VALUE(MID(UPPER(TRIM(D6)),5,1))+VALUE(MID(UPPER(TRIM(D6)),7,1)))+(INT(2*VALUE(MID(UPPER(TRIM(D6)),2,1))/10)+MOD(2*VALUE(MID(UPPER(TRIM(D6)),2,1)),10))+(INT(2*VALUE(MID(UPPER(TRIM(D6)),4,1))/10)+MOD(2*VALUE(MID(UPPER(TRIM(D6)),4,1)),10))+(INT(2*VALUE(MID(UPPER(TRIM(D6)),6,1))/10)+MOD(2*VALUE(MID(UPPER(TRIM(D6)),6,1)),10))+(INT(2*VALUE(MID(UPPER(TRIM(D6)),8,1))/10)+MOD(2*VALUE(MID(UPPER(TRIM(D6)),8,1)),10)),10),10),"0"),RIGHT(UPPER(TRIM(D6)),1)=MID("JABCDEFGHI",MOD(10-MOD((VALUE(MID(UPPER(TRIM(D6)),3,1))+VALUE(MID(UPPER(TRIM(D6)),5,1))+VALUE(MID(UPPER(TRIM(D6)),7,1)))+(INT(2*VALUE(MID(UPPER(TRIM(D6)),2,1))/10)+MOD(2*VALUE(MID(UPPER(TRIM(D6)),2,1)),10))+(INT(2*VALUE(MID(UPPER(TRIM(D6)),4,1))/10)+MOD(2*VALUE(MID(UPPER(TRIM(D6)),4,1)),10))+(INT(2*VALUE(MID(UPPER(TRIM(D6)),6,1))/10)+MOD(2*VALUE(MID(UPPER(TRIM(D6)),6,1)),10))+(INT(2*VALUE(MID(UPPER(TRIM(D6)),8,1))/10)+MOD(2*VALUE(MID(UPPER(TRIM(D6)),8,1)),10)),10),10)+1,1)),"OK","REVISAR")),"REVISAR"))) | Q6: =IF(B6="","",IF(COUNTIFS($B$2:$B$501,B6,$D$2:$D$501,D6)>1,"DUPLICADA","")) | R6: =IF(A6="","",ROUNDUP(MONTH(A6)/3,0))
I7: =IF(E7="","",ROUND(E7*0.21,2)) | J7: =IF(F7="","",ROUND(F7*0.1,2)) | K7: =IF(G7="","",ROUND(G7*0.04,2)) | N7: =IF(A7="","",SUM(E7:K7)-N(L7)) | O7: =IF(OR(A7="",M7=""),"",IF(ABS(M7-N7)<=0.02,"OK","REVISAR")) | P7: =IF(D7="","",IF(LEN(TRIM(D7))<>9,"REVISAR",IFERROR(IF(OR(ISNUMBER(VALUE(LEFT(UPPER(TRIM(D7)),1))),LEFT(UPPER(TRIM(D7)),1)="X",LEFT(UPPER(TRIM(D7)),1)="Y",LEFT(UPPER(TRIM(D7)),1)="Z"),IF(MID("TRWAGMYFPDXBNJZSQVHLCKE",MOD(VALUE(SUBSTITUTE(SUBSTITUTE(SUBSTITUTE(LEFT(UPPER(TRIM(D7)),8),"X","0"),"Y","1"),"Z","2")),23)+1,1)=RIGHT(UPPER(TRIM(D7)),1),"OK","REVISAR"),IF(OR(RIGHT(UPPER(TRIM(D7)),1)=TEXT(MOD(10-MOD((VALUE(MID(UPPER(TRIM(D7)),3,1))+VALUE(MID(UPPER(TRIM(D7)),5,1))+VALUE(MID(UPPER(TRIM(D7)),7,1)))+(INT(2*VALUE(MID(UPPER(TRIM(D7)),2,1))/10)+MOD(2*VALUE(MID(UPPER(TRIM(D7)),2,1)),10))+(INT(2*VALUE(MID(UPPER(TRIM(D7)),4,1))/10)+MOD(2*VALUE(MID(UPPER(TRIM(D7)),4,1)),10))+(INT(2*VALUE(MID(UPPER(TRIM(D7)),6,1))/10)+MOD(2*VALUE(MID(UPPER(TRIM(D7)),6,1)),10))+(INT(2*VALUE(MID(UPPER(TRIM(D7)),8,1))/10)+MOD(2*VALUE(MID(UPPER(TRIM(D7)),8,1)),10)),10),10),"0"),RIGHT(UPPER(TRIM(D7)),1)=MID("JABCDEFGHI",MOD(10-MOD((VALUE(MID(UPPER(TRIM(D7)),3,1))+VALUE(MID(UPPER(TRIM(D7)),5,1))+VALUE(MID(UPPER(TRIM(D7)),7,1)))+(INT(2*VALUE(MID(UPPER(TRIM(D7)),2,1))/10)+MOD(2*VALUE(MID(UPPER(TRIM(D7)),2,1)),10))+(INT(2*VALUE(MID(UPPER(TRIM(D7)),4,1))/10)+MOD(2*VALUE(MID(UPPER(TRIM(D7)),4,1)),10))+(INT(2*VALUE(MID(UPPER(TRIM(D7)),6,1))/10)+MOD(2*VALUE(MID(UPPER(TRIM(D7)),6,1)),10))+(INT(2*VALUE(MID(UPPER(TRIM(D7)),8,1))/10)+MOD(2*VALUE(MID(UPPER(TRIM(D7)),8,1)),10)),10),10)+1,1)),"OK","REVISAR")),"REVISAR"))) | Q7: =IF(B7="","",IF(COUNTIFS($B$2:$B$501,B7,$D$2:$D$501,D7)>1,"DUPLICADA","")) | R7: =IF(A7="","",ROUNDUP(MONTH(A7)/3,0))
I8: =IF(E8="","",ROUND(E8*0.21,2)) | J8: =IF(F8="","",ROUND(F8*0.1,2)) | K8: =IF(G8="","",ROUND(G8*0.04,2)) | N8: =IF(A8="","",SUM(E8:K8)-N(L8)) | O8: =IF(OR(A8="",M8=""),"",IF(ABS(M8-N8)<=0.02,"OK","REVISAR")) | P8: =IF(D8="","",IF(LEN(TRIM(D8))<>9,"REVISAR",IFERROR(IF(OR(ISNUMBER(VALUE(LEFT(UPPER(TRIM(D8)),1))),LEFT(UPPER(TRIM(D8)),1)="X",LEFT(UPPER(TRIM(D8)),1)="Y",LEFT(UPPER(TRIM(D8)),1)="Z"),IF(MID("TRWAGMYFPDXBNJZSQVHLCKE",MOD(VALUE(SUBSTITUTE(SUBSTITUTE(SUBSTITUTE(LEFT(UPPER(TRIM(D8)),8),"X","0"),"Y","1"),"Z","2")),23)+1,1)=RIGHT(UPPER(TRIM(D8)),1),"OK","REVISAR"),IF(OR(RIGHT(UPPER(TRIM(D8)),1)=TEXT(MOD(10-MOD((VALUE(MID(UPPER(TRIM(D8)),3,1))+VALUE(MID(UPPER(TRIM(D8)),5,1))+VALUE(MID(UPPER(TRIM(D8)),7,1)))+(INT(2*VALUE(MID(UPPER(TRIM(D8)),2,1))/10)+MOD(2*VALUE(MID(UPPER(TRIM(D8)),2,1)),10))+(INT(2*VALUE(MID(UPPER(TRIM(D8)),4,1))/10)+MOD(2*VALUE(MID(UPPER(TRIM(D8)),4,1)),10))+(INT(2*VALUE(MID(UPPER(TRIM(D8)),6,1))/10)+MOD(2*VALUE(MID(UPPER(TRIM(D8)),6,1)),10))+(INT(2*VALUE(MID(UPPER(TRIM(D8)),8,1))/10)+MOD(2*VALUE(MID(UPPER(TRIM(D8)),8,1)),10)),10),10),"0"),RIGHT(UPPER(TRIM(D8)),1)=MID("JABCDEFGHI",MOD(10-MOD((VALUE(MID(UPPER(TRIM(D8)),3,1))+VALUE(MID(UPPER(TRIM(D8)),5,1))+VALUE(MID(UPPER(TRIM(D8)),7,1)))+(INT(2*VALUE(MID(UPPER(TRIM(D8)),2,1))/10)+MOD(2*VALUE(MID(UPPER(TRIM(D8)),2,1)),10))+(INT(2*VALUE(MID(UPPER(TRIM(D8)),4,1))/10)+MOD(2*VALUE(MID(UPPER(TRIM(D8)),4,1)),10))+(INT(2*VALUE(MID(UPPER(TRIM(D8)),6,1))/10)+MOD(2*VALUE(MID(UPPER(TRIM(D8)),6,1)),10))+(INT(2*VALUE(MID(UPPER(TRIM(D8)),8,1))/10)+MOD(2*VALUE(MID(UPPER(TRIM(D8)),8,1)),10)),10),10)+1,1)),"OK","REVISAR")),"REVISAR"))) | Q8: =IF(B8="","",IF(COUNTIFS($B$2:$B$501,B8,$D$2:$D$501,D8)>1,"DUPLICADA","")) | R8: =IF(A8="","",ROUNDUP(MONTH(A8)/3,0))
I9: =IF(E9="","",ROUND(E9*0.21,2)) | J9: =IF(F9="","",ROUND(F9*0.1,2)) | K9: =IF(G9="","",ROUND(G9*0.04,2)) | N9: =IF(A9="","",SUM(E9:K9)-N(L9)) | O9: =IF(OR(A9="",M9=""),"",IF(ABS(M9-N9)<=0.02,"OK","REVISAR")) | P9: =IF(D9="","",IF(LEN(TRIM(D9))<>9,"REVISAR",IFERROR(IF(OR(ISNUMBER(VALUE(LEFT(UPPER(TRIM(D9)),1))),LEFT(UPPER(TRIM(D9)),1)="X",LEFT(UPPER(TRIM(D9)),1)="Y",LEFT(UPPER(TRIM(D9)),1)="Z"),IF(MID("TRWAGMYFPDXBNJZSQVHLCKE",MOD(VALUE(SUBSTITUTE(SUBSTITUTE(SUBSTITUTE(LEFT(UPPER(TRIM(D9)),8),"X","0"),"Y","1"),"Z","2")),23)+1,1)=RIGHT(UPPER(TRIM(D9)),1),"OK","REVISAR"),IF(OR(RIGHT(UPPER(TRIM(D9)),1)=TEXT(MOD(10-MOD((VALUE(MID(UPPER(TRIM(D9)),3,1))+VALUE(MID(UPPER(TRIM(D9)),5,1))+VALUE(MID(UPPER(TRIM(D9)),7,1)))+(INT(2*VALUE(MID(UPPER(TRIM(D9)),2,1))/10)+MOD(2*VALUE(MID(UPPER(TRIM(D9)),2,1)),10))+(INT(2*VALUE(MID(UPPER(TRIM(D9)),4,1))/10)+MOD(2*VALUE(MID(UPPER(TRIM(D9)),4,1)),10))+(INT(2*VALUE(MID(UPPER(TRIM(D9)),6,1))/10)+MOD(2*VALUE(MID(UPPER(TRIM(D9)),6,1)),10))+(INT(2*VALUE(MID(UPPER(TRIM(D9)),8,1))/10)+MOD(2*VALUE(MID(UPPER(TRIM(D9)),8,1)),10)),10),10),"0"),RIGHT(UPPER(TRIM(D9)),1)=MID("JABCDEFGHI",MOD(10-MOD((VALUE(MID(UPPER(TRIM(D9)),3,1))+VALUE(MID(UPPER(TRIM(D9)),5,1))+VALUE(MID(UPPER(TRIM(D9)),7,1)))+(INT(2*VALUE(MID(UPPER(TRIM(D9)),2,1))/10)+MOD(2*VALUE(MID(UPPER(TRIM(D9)),2,1)),10))+(INT(2*VALUE(MID(UPPER(TRIM(D9)),4,1))/10)+MOD(2*VALUE(MID(UPPER(TRIM(D9)),4,1)),10))+(INT(2*VALUE(MID(UPPER(TRIM(D9)),6,1))/10)+MOD(2*VALUE(MID(UPPER(TRIM(D9)),6,1)),10))+(INT(2*VALUE(MID(UPPER(TRIM(D9)),8,1))/10)+MOD(2*VALUE(MID(UPPER(TRIM(D9)),8,1)),10)),10),10)+1,1)),"OK","REVISAR")),"REVISAR"))) | Q9: =IF(B9="","",IF(COUNTIFS($B$2:$B$501,B9,$D$2:$D$501,D9)>1,"DUPLICADA","")) | R9: =IF(A9="","",ROUNDUP(MONTH(A9)/3,0))
I10: =IF(E10="","",ROUND(E10*0.21,2)) | J10: =IF(F10="","",ROUND(F10*0.1,2)) | K10: =IF(G10="","",ROUND(G10*0.04,2)) | N10: =IF(A10="","",SUM(E10:K10)-N(L10)) | O10: =IF(OR(A10="",M10=""),"",IF(ABS(M10-N10)<=0.02,"OK","REVISAR")) | P10: =IF(D10="","",IF(LEN(TRIM(D10))<>9,"REVISAR",IFERROR(IF(OR(ISNUMBER(VALUE(LEFT(UPPER(TRIM(D10)),1))),LEFT(UPPER(TRIM(D10)),1)="X",LEFT(UPPER(TRIM(D10)),1)="Y",LEFT(UPPER(TRIM(D10)),1)="Z"),IF(MID("TRWAGMYFPDXBNJZSQVHLCKE",MOD(VALUE(SUBSTITUTE(SUBSTITUTE(SUBSTITUTE(LEFT(UPPER(TRIM(D10)),8),"X","0"),"Y","1"),"Z","2")),23)+1,1)=RIGHT(UPPER(TRIM(D10)),1),"OK","REVISAR"),IF(OR(RIGHT(UPPER(TRIM(D10)),1)=TEXT(MOD(10-MOD((VALUE(MID(UPPER(TRIM(D10)),3,1))+VALUE(MID(UPPER(TRIM(D10)),5,1))+VALUE(MID(UPPER(TRIM(D10)),7,1)))+(INT(2*VALUE(MID(UPPER(TRIM(D10)),2,1))/10)+MOD(2*VALUE(MID(UPPER(TRIM(D10)),2,1)),10))+(INT(2*VALUE(MID(UPPER(TRIM(D10)),4,1))/10)+MOD(2*VALUE(MID(UPPER(TRIM(D10)),4,1)),10))+(INT(2*VALUE(MID(UPPER(TRIM(D10)),6,1))/10)+MOD(2*VALUE(MID(UPPER(TRIM(D10)),6,1)),10))+(INT(2*VALUE(MID(UPPER(TRIM(D10)),8,1))/10)+MOD(2*VALUE(MID(UPPER(TRIM(D10)),8,1)),10)),10),10),"0"),RIGHT(UPPER(TRIM(D10)),1)=MID("JABCDEFGHI",MOD(10-MOD((VALUE(MID(UPPER(TRIM(D10)),3,1))+VALUE(MID(UPPER(TRIM(D10)),5,1))+VALUE(MID(UPPER(TRIM(D10)),7,1)))+(INT(2*VALUE(MID(UPPER(TRIM(D10)),2,1))/10)+MOD(2*VALUE(MID(UPPER(TRIM(D10)),2,1)),10))+(INT(2*VALUE(MID(UPPER(TRIM(D10)),4,1))/10)+MOD(2*VALUE(MID(UPPER(TRIM(D10)),4,1)),10))+(INT(2*VALUE(MID(UPPER(TRIM(D10)),6,1))/10)+MOD(2*VALUE(MID(UPPER(TRIM(D10)),6,1)),10))+(INT(2*VALUE(MID(UPPER(TRIM(D10)),8,1))/10)+MOD(2*VALUE(MID(UPPER(TRIM(D10)),8,1)),10)),10),10)+1,1)),"OK","REVISAR")),"REVISAR"))) | Q10: =IF(B10="","",IF(COUNTIFS($B$2:$B$501,B10,$D$2:$D$501,D10)>1,"DUPLICADA","")) | R10: =IF(A10="","",ROUNDUP(MONTH(A10)/3,0))
I11: =IF(E11="","",ROUND(E11*0.21,2)) | J11: =IF(F11="","",ROUND(F11*0.1,2)) | K11: =IF(G11="","",ROUND(G11*0.04,2)) | N11: =IF(A11="","",SUM(E11:K11)-N(L11)) | O11: =IF(OR(A11="",M11=""),"",IF(ABS(M11-N11)<=0.02,"OK","REVISAR")) | P11: =IF(D11="","",IF(LEN(TRIM(D11))<>9,"REVISAR",IFERROR(IF(OR(ISNUMBER(VALUE(LEFT(UPPER(TRIM(D11)),1))),LEFT(UPPER(TRIM(D11)),1)="X",LEFT(UPPER(TRIM(D11)),1)="Y",LEFT(UPPER(TRIM(D11)),1)="Z"),IF(MID("TRWAGMYFPDXBNJZSQVHLCKE",MOD(VALUE(SUBSTITUTE(SUBSTITUTE(SUBSTITUTE(LEFT(UPPER(TRIM(D11)),8),"X","0"),"Y","1"),"Z","2")),23)+1,1)=RIGHT(UPPER(TRIM(D11)),1),"OK","REVISAR"),IF(OR(RIGHT(UPPER(TRIM(D11)),1)=TEXT(MOD(10-MOD((VALUE(MID(UPPER(TRIM(D11)),3,1))+VALUE(MID(UPPER(TRIM(D11)),5,1))+VALUE(MID(UPPER(TRIM(D11)),7,1)))+(INT(2*VALUE(MID(UPPER(TRIM(D11)),2,1))/10)+MOD(2*VALUE(MID(UPPER(TRIM(D11)),2,1)),10))+(INT(2*VALUE(MID(UPPER(TRIM(D11)),4,1))/10)+MOD(2*VALUE(MID(UPPER(TRIM(D11)),4,1)),10))+(INT(2*VALUE(MID(UPPER(TRIM(D11)),6,1))/10)+MOD(2*VALUE(MID(UPPER(TRIM(D11)),6,1)),10))+(INT(2*VALUE(MID(UPPER(TRIM(D11)),8,1))/10)+MOD(2*VALUE(MID(UPPER(TRIM(D11)),8,1)),10)),10),10),"0"),RIGHT(UPPER(TRIM(D11)),1)=MID("JABCDEFGHI",MOD(10-MOD((VALUE(MID(UPPER(TRIM(D11)),3,1))+VALUE(MID(UPPER(TRIM(D11)),5,1))+VALUE(MID(UPPER(TRIM(D11)),7,1)))+(INT(2*VALUE(MID(UPPER(TRIM(D11)),2,1))/10)+MOD(2*VALUE(MID(UPPER(TRIM(D11)),2,1)),10))+(INT(2*VALUE(MID(UPPER(TRIM(D11)),4,1))/10)+MOD(2*VALUE(MID(UPPER(TRIM(D11)),4,1)),10))+(INT(2*VALUE(MID(UPPER(TRIM(D11)),6,1))/10)+MOD(2*VALUE(MID(UPPER(TRIM(D11)),6,1)),10))+(INT(2*VALUE(MID(UPPER(TRIM(D11)),8,1))/10)+MOD(2*VALUE(MID(UPPER(TRIM(D11)),8,1)),10)),10),10)+1,1)),"OK","REVISAR")),"REVISAR"))) | Q11: =IF(B11="","",IF(COUNTIFS($B$2:$B$501,B11,$D$2:$D$501,D11)>1,"DUPLICADA","")) | R11: =IF(A11="","",ROUNDUP(MONTH(A11)/3,0))
I12: =IF(E12="","",ROUND(E12*0.21,2)) | J12: =IF(F12="","",ROUND(F12*0.1,2)) | K12: =IF(G12="","",ROUND(G12*0.04,2)) | N12: =IF(A12="","",SUM(E12:K12)-N(L12)) | O12: =IF(OR(A12="",M12=""),"",IF(ABS(M12-N12)<=0.02,"OK","REVISAR")) | P12: =IF(D12="","",IF(LEN(TRIM(D12))<>9,"REVISAR",IFERROR(IF(OR(ISNUMBER(VALUE(LEFT(UPPER(TRIM(D12)),1))),LEFT(UPPER(TRIM(D12)),1)="X",LEFT(UPPER(TRIM(D12)),1)="Y",LEFT(UPPER(TRIM(D12)),1)="Z"),IF(MID("TRWAGMYFPDXBNJZSQVHLCKE",MOD(VALUE(SUBSTITUTE(SUBSTITUTE(SUBSTITUTE(LEFT(UPPER(TRIM(D12)),8),"X","0"),"Y","1"),"Z","2")),23)+1,1)=RIGHT(UPPER(TRIM(D12)),1),"OK","REVISAR"),IF(OR(RIGHT(UPPER(TRIM(D12)),1)=TEXT(MOD(10-MOD((VALUE(MID(UPPER(TRIM(D12)),3,1))+VALUE(MID(UPPER(TRIM(D12)),5,1))+VALUE(MID(UPPER(TRIM(D12)),7,1)))+(INT(2*VALUE(MID(UPPER(TRIM(D12)),2,1))/10)+MOD(2*VALUE(MID(UPPER(TRIM(D12)),2,1)),10))+(INT(2*VALUE(MID(UPPER(TRIM(D12)),4,1))/10)+MOD(2*VALUE(MID(UPPER(TRIM(D12)),4,1)),10))+(INT(2*VALUE(MID(UPPER(TRIM(D12)),6,1))/10)+MOD(2*VALUE(MID(UPPER(TRIM(D12)),6,1)),10))+(INT(2*VALUE(MID(UPPER(TRIM(D12)),8,1))/10)+MOD(2*VALUE(MID(UPPER(TRIM(D12)),8,1)),10)),10),10),"0"),RIGHT(UPPER(TRIM(D12)),1)=MID("JABCDEFGHI",MOD(10-MOD((VALUE(MID(UPPER(TRIM(D12)),3,1))+VALUE(MID(UPPER(TRIM(D12)),5,1))+VALUE(MID(UPPER(TRIM(D12)),7,1)))+(INT(2*VALUE(MID(UPPER(TRIM(D12)),2,1))/10)+MOD(2*VALUE(MID(UPPER(TRIM(D12)),2,1)),10))+(INT(2*VALUE(MID(UPPER(TRIM(D12)),4,1))/10)+MOD(2*VALUE(MID(UPPER(TRIM(D12)),4,1)),10))+(INT(2*VALUE(MID(UPPER(TRIM(D12)),6,1))/10)+MOD(2*VALUE(MID(UPPER(TRIM(D12)),6,1)),10))+(INT(2*VALUE(MID(UPPER(TRIM(D12)),8,1))/10)+MOD(2*VALUE(MID(UPPER(TRIM(D12)),8,1)),10)),10),10)+1,1)),"OK","REVISAR")),"REVISAR"))) | Q12: =IF(B12="","",IF(COUNTIFS($B$2:$B$501,B12,$D$2:$D$501,D12)>1,"DUPLICADA","")) | R12: =IF(A12="","",ROUNDUP(MONTH(A12)/3,0))
I13: =IF(E13="","",ROUND(E13*0.21,2)) | J13: =IF(F13="","",ROUND(F13*0.1,2)) | K13: =IF(G13="","",ROUND(G13*0.04,2)) | N13: =IF(A13="","",SUM(E13:K13)-N(L13)) | O13: =IF(OR(A13="",M13=""),"",IF(ABS(M13-N13)<=0.02,"OK","REVISAR")) | P13: =IF(D13="","",IF(LEN(TRIM(D13))<>9,"REVISAR",IFERROR(IF(OR(ISNUMBER(VALUE(LEFT(UPPER(TRIM(D13)),1))),LEFT(UPPER(TRIM(D13)),1)="X",LEFT(UPPER(TRIM(D13)),1)="Y",LEFT(UPPER(TRIM(D13)),1)="Z"),IF(MID("TRWAGMYFPDXBNJZSQVHLCKE",MOD(VALUE(SUBSTITUTE(SUBSTITUTE(SUBSTITUTE(LEFT(UPPER(TRIM(D13)),8),"X","0"),"Y","1"),"Z","2")),23)+1,1)=RIGHT(UPPER(TRIM(D13)),1),"OK","REVISAR"),IF(OR(RIGHT(UPPER(TRIM(D13)),1)=TEXT(MOD(10-MOD((VALUE(MID(UPPER(TRIM(D13)),3,1))+VALUE(MID(UPPER(TRIM(D13)),5,1))+VALUE(MID(UPPER(TRIM(D13)),7,1)))+(INT(2*VALUE(MID(UPPER(TRIM(D13)),2,1))/10)+MOD(2*VALUE(MID(UPPER(TRIM(D13)),2,1)),10))+(INT(2*VALUE(MID(UPPER(TRIM(D13)),4,1))/10)+MOD(2*VALUE(MID(UPPER(TRIM(D13)),4,1)),10))+(INT(2*VALUE(MID(UPPER(TRIM(D13)),6,1))/10)+MOD(2*VALUE(MID(UPPER(TRIM(D13)),6,1)),10))+(INT(2*VALUE(MID(UPPER(TRIM(D13)),8,1))/10)+MOD(2*VALUE(MID(UPPER(TRIM(D13)),8,1)),10)),10),10),"0"),RIGHT(UPPER(TRIM(D13)),1)=MID("JABCDEFGHI",MOD(10-MOD((VALUE(MID(UPPER(TRIM(D13)),3,1))+VALUE(MID(UPPER(TRIM(D13)),5,1))+VALUE(MID(UPPER(TRIM(D13)),7,1)))+(INT(2*VALUE(MID(UPPER(TRIM(D13)),2,1))/10)+MOD(2*VALUE(MID(UPPER(TRIM(D13)),2,1)),10))+(INT(2*VALUE(MID(UPPER(TRIM(D13)),4,1))/10)+MOD(2*VALUE(MID(UPPER(TRIM(D13)),4,1)),10))+(INT(2*VALUE(MID(UPPER(TRIM(D13)),6,1))/10)+MOD(2*VALUE(MID(UPPER(TRIM(D13)),6,1)),10))+(INT(2*VALUE(MID(UPPER(TRIM(D13)),8,1))/10)+MOD(2*VALUE(MID(UPPER(TRIM(D13)),8,1)),10)),10),10)+1,1)),"OK","REVISAR")),"REVISAR"))) | Q13: =IF(B13="","",IF(COUNTIFS($B$2:$B$501,B13,$D$2:$D$501,D13)>1,"DUPLICADA","")) | R13: =IF(A13="","",ROUNDUP(MONTH(A13)/3,0))
I14: =IF(E14="","",ROUND(E14*0.21,2)) | J14: =IF(F14="","",ROUND(F14*0.1,2)) | K14: =IF(G14="","",ROUND(G14*0.04,2)) | N14: =IF(A14="","",SUM(E14:K14)-N(L14)) | O14: =IF(OR(A14="",M14=""),"",IF(ABS(M14-N14)<=0.02,"OK","REVISAR")) | P14: =IF(D14="","",IF(LEN(TRIM(D14))<>9,"REVISAR",IFERROR(IF(OR(ISNUMBER(VALUE(LEFT(UPPER(TRIM(D14)),1))),LEFT(UPPER(TRIM(D14)),1)="X",LEFT(UPPER(TRIM(D14)),1)="Y",LEFT(UPPER(TRIM(D14)),1)="Z"),IF(MID("TRWAGMYFPDXBNJZSQVHLCKE",MOD(VALUE(SUBSTITUTE(SUBSTITUTE(SUBSTITUTE(LEFT(UPPER(TRIM(D14)),8),"X","0"),"Y","1"),"Z","2")),23)+1,1)=RIGHT(UPPER(TRIM(D14)),1),"OK","REVISAR"),IF(OR(RIGHT(UPPER(TRIM(D14)),1)=TEXT(MOD(10-MOD((VALUE(MID(UPPER(TRIM(D14)),3,1))+VALUE(MID(UPPER(TRIM(D14)),5,1))+VALUE(MID(UPPER(TRIM(D14)),7,1)))+(INT(2*VALUE(MID(UPPER(TRIM(D14)),2,1))/10)+MOD(2*VALUE(MID(UPPER(TRIM(D14)),2,1)),10))+(INT(2*VALUE(MID(UPPER(TRIM(D14)),4,1))/10)+MOD(2*VALUE(MID(UPPER(TRIM(D14)),4,1)),10))+(INT(2*VALUE(MID(UPPER(TRIM(D14)),6,1))/10)+MOD(2*VALUE(MID(UPPER(TRIM(D14)),6,1)),10))+(INT(2*VALUE(MID(UPPER(TRIM(D14)),8,1))/10)+MOD(2*VALUE(MID(UPPER(TRIM(D14)),8,1)),10)),10),10),"0"),RIGHT(UPPER(TRIM(D14)),1)=MID("JABCDEFGHI",MOD(10-MOD((VALUE(MID(UPPER(TRIM(D14)),3,1))+VALUE(MID(UPPER(TRIM(D14)),5,1))+VALUE(MID(UPPER(TRIM(D14)),7,1)))+(INT(2*VALUE(MID(UPPER(TRIM(D14)),2,1))/10)+MOD(2*VALUE(MID(UPPER(TRIM(D14)),2,1)),10))+(INT(2*VALUE(MID(UPPER(TRIM(D14)),4,1))/10)+MOD(2*VALUE(MID(UPPER(TRIM(D14)),4,1)),10))+(INT(2*VALUE(MID(UPPER(TRIM(D14)),6,1))/10)+MOD(2*VALUE(MID(UPPER(TRIM(D14)),6,1)),10))+(INT(2*VALUE(MID(UPPER(TRIM(D14)),8,1))/10)+MOD(2*VALUE(MID(UPPER(TRIM(D14)),8,1)),10)),10),10)+1,1)),"OK","REVISAR")),"REVISAR"))) | Q14: =IF(B14="","",IF(COUNTIFS($B$2:$B$501,B14,$D$2:$D$501,D14)>1,"DUPLICADA","")) | R14: =IF(A14="","",ROUNDUP(MONTH(A14)/3,0))
I15: =IF(E15="","",ROUND(E15*0.21,2)) | J15: =IF(F15="","",ROUND(F15*0.1,2)) | K15: =IF(G15="","",ROUND(G15*0.04,2)) | N15: =IF(A15="","",SUM(E15:K15)-N(L15)) | O15: =IF(OR(A15="",M15=""),"",IF(ABS(M15-N15)<=0.02,"OK","REVISAR")) | P15: =IF(D15="","",IF(LEN(TRIM(D15))<>9,"REVISAR",IFERROR(IF(OR(ISNUMBER(VALUE(LEFT(UPPER(TRIM(D15)),1))),LEFT(UPPER(TRIM(D15)),1)="X",LEFT(UPPER(TRIM(D15)),1)="Y",LEFT(UPPER(TRIM(D15)),1)="Z"),IF(MID("TRWAGMYFPDXBNJZSQVHLCKE",MOD(VALUE(SUBSTITUTE(SUBSTITUTE(SUBSTITUTE(LEFT(UPPER(TRIM(D15)),8),"X","0"),"Y","1"),"Z","2")),23)+1,1)=RIGHT(UPPER(TRIM(D15)),1),"OK","REVISAR"),IF(OR(RIGHT(UPPER(TRIM(D15)),1)=TEXT(MOD(10-MOD((VALUE(MID(UPPER(TRIM(D15)),3,1))+VALUE(MID(UPPER(TRIM(D15)),5,1))+VALUE(MID(UPPER(TRIM(D15)),7,1)))+(INT(2*VALUE(MID(UPPER(TRIM(D15)),2,1))/10)+MOD(2*VALUE(MID(UPPER(TRIM(D15)),2,1)),10))+(INT(2*VALUE(MID(UPPER(TRIM(D15)),4,1))/10)+MOD(2*VALUE(MID(UPPER(TRIM(D15)),4,1)),10))+(INT(2*VALUE(MID(UPPER(TRIM(D15)),6,1))/10)+MOD(2*VALUE(MID(UPPER(TRIM(D15)),6,1)),10))+(INT(2*VALUE(MID(UPPER(TRIM(D15)),8,1))/10)+MOD(2*VALUE(MID(UPPER(TRIM(D15)),8,1)),10)),10),10),"0"),RIGHT(UPPER(TRIM(D15)),1)=MID("JABCDEFGHI",MOD(10-MOD((VALUE(MID(UPPER(TRIM(D15)),3,1))+VALUE(MID(UPPER(TRIM(D15)),5,1))+VALUE(MID(UPPER(TRIM(D15)),7,1)))+(INT(2*VALUE(MID(UPPER(TRIM(D15)),2,1))/10)+MOD(2*VALUE(MID(UPPER(TRIM(D15)),2,1)),10))+(INT(2*VALUE(MID(UPPER(TRIM(D15)),4,1))/10)+MOD(2*VALUE(MID(UPPER(TRIM(D15)),4,1)),10))+(INT(2*VALUE(MID(UPPER(TRIM(D15)),6,1))/10)+MOD(2*VALUE(MID(UPPER(TRIM(D15)),6,1)),10))+(INT(2*VALUE(MID(UPPER(TRIM(D15)),8,1))/10)+MOD(2*VALUE(MID(UPPER(TRIM(D15)),8,1)),10)),10),10)+1,1)),"OK","REVISAR")),"REVISAR"))) | Q15: =IF(B15="","",IF(COUNTIFS($B$2:$B$501,B15,$D$2:$D$501,D15)>1,"DUPLICADA","")) | R15: =IF(A15="","",ROUNDUP(MONTH(A15)/3,0))
I16: =IF(E16="","",ROUND(E16*0.21,2)) | J16: =IF(F16="","",ROUND(F16*0.1,2)) | K16: =IF(G16="","",ROUND(G16*0.04,2)) | N16: =IF(A16="","",SUM(E16:K16)-N(L16)) | O16: =IF(OR(A16="",M16=""),"",IF(ABS(M16-N16)<=0.02,"OK","REVISAR")) | P16: =IF(D16="","",IF(LEN(TRIM(D16))<>9,"REVISAR",IFERROR(IF(OR(ISNUMBER(VALUE(LEFT(UPPER(TRIM(D16)),1))),LEFT(UPPER(TRIM(D16)),1)="X",LEFT(UPPER(TRIM(D16)),1)="Y",LEFT(UPPER(TRIM(D16)),1)="Z"),IF(MID("TRWAGMYFPDXBNJZSQVHLCKE",MOD(VALUE(SUBSTITUTE(SUBSTITUTE(SUBSTITUTE(LEFT(UPPER(TRIM(D16)),8),"X","0"),"Y","1"),"Z","2")),23)+1,1)=RIGHT(UPPER(TRIM(D16)),1),"OK","REVISAR"),IF(OR(RIGHT(UPPER(TRIM(D16)),1)=TEXT(MOD(10-MOD((VALUE(MID(UPPER(TRIM(D16)),3,1))+VALUE(MID(UPPER(TRIM(D16)),5,1))+VALUE(MID(UPPER(TRIM(D16)),7,1)))+(INT(2*VALUE(MID(UPPER(TRIM(D16)),2,1))/10)+MOD(2*VALUE(MID(UPPER(TRIM(D16)),2,1)),10))+(INT(2*VALUE(MID(UPPER(TRIM(D16)),4,1))/10)+MOD(2*VALUE(MID(UPPER(TRIM(D16)),4,1)),10))+(INT(2*VALUE(MID(UPPER(TRIM(D16)),6,1))/10)+MOD(2*VALUE(MID(UPPER(TRIM(D16)),6,1)),10))+(INT(2*VALUE(MID(UPPER(TRIM(D16)),8,1))/10)+MOD(2*VALUE(MID(UPPER(TRIM(D16)),8,1)),10)),10),10),"0"),RIGHT(UPPER(TRIM(D16)),1)=MID("JABCDEFGHI",MOD(10-MOD((VALUE(MID(UPPER(TRIM(D16)),3,1))+VALUE(MID(UPPER(TRIM(D16)),5,1))+VALUE(MID(UPPER(TRIM(D16)),7,1)))+(INT(2*VALUE(MID(UPPER(TRIM(D16)),2,1))/10)+MOD(2*VALUE(MID(UPPER(TRIM(D16)),2,1)),10))+(INT(2*VALUE(MID(UPPER(TRIM(D16)),4,1))/10)+MOD(2*VALUE(MID(UPPER(TRIM(D16)),4,1)),10))+(INT(2*VALUE(MID(UPPER(TRIM(D16)),6,1))/10)+MOD(2*VALUE(MID(UPPER(TRIM(D16)),6,1)),10))+(INT(2*VALUE(MID(UPPER(TRIM(D16)),8,1))/10)+MOD(2*VALUE(MID(UPPER(TRIM(D16)),8,1)),10)),10),10)+1,1)),"OK","REVISAR")),"REVISAR"))) | Q16: =IF(B16="","",IF(COUNTIFS($B$2:$B$501,B16,$D$2:$D$501,D16)>1,"DUPLICADA","")) | R16: =IF(A16="","",ROUNDUP(MONTH(A16)/3,0))
... I501: =IF(E501="","",ROUND(E501*0.21,2)) | J501: =IF(F501="","",ROUND(F501*0.1,2)) | K501: =IF(G501="","",ROUND(G501*0.04,2)) | N501: =IF(A501="","",SUM(E501:K501)-N(L501)) | O501: =IF(OR(A501="",M501=""),"",IF(ABS(M501-N501)<=0.02,"OK","REVISAR")) | P501: =IF(D501="","",IF(LEN(TRIM(D501))<>9,"REVISAR",IFERROR(IF(OR(ISNUMBER(VALUE(LEFT(UPPER(TRIM(D501)),1))),LEFT(UPPER(TRIM(D501)),1)="X",LEFT(UPPER(TRIM(D501)),1)="Y",LEFT(UPPER(TRIM(D501)),1)="Z"),IF(MID("TRWAGMYFPDXBNJZSQVHLCKE",MOD(VALUE(SUBSTITUTE(SUBSTITUTE(SUBSTITUTE(LEFT(UPPER(TRIM(D501)),8),"X","0"),"Y","1"),"Z","2")),23)+1,1)=RIGHT(UPPER(TRIM(D501)),1),"OK","REVISAR"),IF(OR(RIGHT(UPPER(TRIM(D501)),1)=TEXT(MOD(10-MOD((VALUE(MID(UPPER(TRIM(D501)),3,1))+VALUE(MID(UPPER(TRIM(D501)),5,1))+VALUE(MID(UPPER(TRIM(D501)),7,1)))+(INT(2*VALUE(MID(UPPER(TRIM(D501)),2,1))/10)+MOD(2*VALUE(MID(UPPER(TRIM(D501)),2,1)),10))+(INT(2*VALUE(MID(UPPER(TRIM(D501)),4,1))/10)+MOD(2*VALUE(MID(UPPER(TRIM(D501)),4,1)),10))+(INT(2*VALUE(MID(UPPER(TRIM(D501)),6,1))/10)+MOD(2*VALUE(MID(UPPER(TRIM(D501)),6,1)),10))+(INT(2*VALUE(MID(UPPER(TRIM(D501)),8,1))/10)+MOD(2*VALUE(MID(UPPER(TRIM(D501)),8,1)),10)),10),10),"0"),RIGHT(UPPER(TRIM(D501)),1)=MID("JABCDEFGHI",MOD(10-MOD((VALUE(MID(UPPER(TRIM(D501)),3,1))+VALUE(MID(UPPER(TRIM(D501)),5,1))+VALUE(MID(UPPER(TRIM(D501)),7,1)))+(INT(2*VALUE(MID(UPPER(TRIM(D501)),2,1))/10)+MOD(2*VALUE(MID(UPPER(TRIM(D501)),2,1)),10))+(INT(2*VALUE(MID(UPPER(TRIM(D501)),4,1))/10)+MOD(2*VALUE(MID(UPPER(TRIM(D501)),4,1)),10))+(INT(2*VALUE(MID(UPPER(TRIM(D501)),6,1))/10)+MOD(2*VALUE(MID(UPPER(TRIM(D501)),6,1)),10))+(INT(2*VALUE(MID(UPPER(TRIM(D501)),8,1))/10)+MOD(2*VALUE(MID(UPPER(TRIM(D501)),8,1)),10)),10),10)+1,1)),"OK","REVISAR")),"REVISAR"))) | Q501: =IF(B501="","",IF(COUNTIFS($B$2:$B$501,B501,$D$2:$D$501,D501)>1,"DUPLICADA","")) | R501: =IF(A501="","",ROUNDUP(MONTH(A501)/3,0))

Sheet Resumen 303
A1: Resumen orientativo del modelo 303 por trimestre (€) | B1: 1T | C1: 2T | D1: 3T | E1: 4T
A2: Base devengada 21 % | B2: =SUMIFS(Emitidas!E$2:E$501,Emitidas!$R$2:$R$501,1) | C2: =SUMIFS(Emitidas!E$2:E$501,Emitidas!$R$2:$R$501,2) | D2: =SUMIFS(Emitidas!E$2:E$501,Emitidas!$R$2:$R$501,3) | E2: =SUMIFS(Emitidas!E$2:E$501,Emitidas!$R$2:$R$501,4)
A3: Cuota devengada 21 % | B3: =SUMIFS(Emitidas!I$2:I$501,Emitidas!$R$2:$R$501,1) | C3: =SUMIFS(Emitidas!I$2:I$501,Emitidas!$R$2:$R$501,2) | D3: =SUMIFS(Emitidas!I$2:I$501,Emitidas!$R$2:$R$501,3) | E3: =SUMIFS(Emitidas!I$2:I$501,Emitidas!$R$2:$R$501,4)
